biomesToSpawnIn=desert,deserthills,beach
weight=5
embed_into_distance=4
acceptable_target_blocks=stone,grass,dirt,sand,gravel
dimensions=8,12,11
allowable_overhang=0
max_cut_in=2
cut_in_buffer=1
max_leveling=2
leveling_buffer=1
preserve_water=0
preserve_lava=0
preserve_plants=0
random_height_offset=1,5

rule1=0,100,stone_slab-1
rule2=0,100,sandstone-2
rule3=0,100,sandstone
rule4=0,100,sandstone-1
rule5=0,100,double_stone_slab-1
rule6=0,100,preserveBlock
rule7=0,100,preserveBlock,MobSpawner:Skeleton,MobSpawner:Skeleton,MobSpawner:Skeleton,MobSpawner:Skeleton,MobSpawner:SilverSkeleton

layer
3,3,3,3,3,3,3,3,3,3,3
3,7,3,3,3,3,3,3,3,3,3
3,3,3,3,3,3,3,3,3,3,3
3,3,3,3,3,3,3,3,3,3,3
3,3,3,3,3,3,3,3,3,3,3
3,3,3,3,3,3,3,3,3,3,3
3,3,3,3,3,3,3,3,3,3,3
3,3,3,3,3,3,3,3,3,3,3
3,3,3,3,3,3,3,3,3,3,3
3,3,3,3,3,3,3,3,3,3,3
3,3,3,3,3,3,3,3,3,3,3
3,3,3,3,3,3,3,3,3,3,3
endlayer


layer
1,1,1,1,6,6,6,1,1,1,1
1,2,6,6,6,6,4,2,2,2,1
1,6,6,6,6,6,6,6,6,2,1
1,6,6,6,6,6,6,6,6,2,1
6,6,6,6,6,6,6,6,6,2,1
6,6,6,6,6,6,6,6,6,2,1
6,6,6,6,6,6,6,6,6,3,1
1,3,6,6,6,6,6,6,6,3,1
1,3,6,6,6,6,6,6,6,3,1
1,3,6,6,6,6,6,6,6,3,1
1,3,3,3,3,3,3,3,3,3,1
1,1,1,1,1,1,1,1,1,1,1
endlayer

layer
6,6,6,6,6,6,6,6,6,6,6
6,6,6,6,6,6,4,6,6,2,6
6,6,6,6,6,6,6,6,6,2,6
6,6,6,6,6,6,6,6,6,6,6
6,6,6,6,6,6,6,6,6,6,6
6,6,6,6,6,6,6,6,6,2,6
6,6,6,6,6,6,6,6,6,3,6
6,3,6,6,6,6,6,6,6,3,6
6,3,6,6,6,6,6,6,6,3,6
6,3,6,6,6,6,6,6,6,3,6
6,6,3,3,6,3,3,3,3,3,6
6,6,6,6,6,6,6,6,6,6,6
endlayer

layer
6,6,6,6,6,6,6,6,6,6,6
6,6,6,6,6,6,6,6,6,2,6
6,6,6,6,6,6,6,6,6,2,6
6,6,6,6,6,6,6,6,6,6,6
6,6,6,6,6,6,6,6,6,6,6
6,6,6,6,6,6,6,6,6,2,6
6,6,6,6,6,6,6,6,6,3,6
6,3,6,6,6,6,6,6,6,3,6
6,3,6,6,6,6,6,6,6,3,6
6,3,6,6,6,6,6,6,6,3,6
6,6,3,3,6,3,3,3,3,3,6
6,6,6,6,6,6,6,6,6,6,6
endlayer

layer
6,6,6,6,6,6,6,1,1,6,6
6,6,6,6,6,6,6,2,2,2,6
6,6,6,6,6,6,6,6,3,2,6
6,6,6,6,6,6,6,6,6,2,1
6,6,6,6,6,6,6,6,3,2,1
6,6,6,6,6,6,6,6,3,2,6
6,6,6,6,6,3,2,3,3,3,6
6,3,3,3,2,2,2,3,3,3,6
6,3,3,3,6,3,3,3,3,3,6
6,3,6,3,6,3,3,3,3,3,6
6,6,3,3,6,3,3,3,3,3,6
6,6,6,6,6,6,6,6,6,6,6
endlayer

layer
6,6,6,1,1,1,1,1,1,1,6
6,6,6,6,6,5,5,5,5,1,1
6,6,6,6,6,6,6,6,5,5,1
1,6,6,6,6,6,6,6,5,5,1
1,5,6,6,6,6,6,6,5,5,1
1,5,6,6,6,6,6,5,5,5,1
1,5,6,6,6,6,3,5,5,5,1
1,5,3,3,3,3,3,5,5,5,1
1,5,3,3,6,3,3,5,5,5,1
1,6,6,5,6,5,5,5,5,5,1
1,6,5,5,6,5,5,5,5,1,1
6,6,1,1,6,1,1,1,1,1,6
endlayer

layer
6,6,6,6,6,6,6,6,6,6,6
6,6,6,6,6,6,6,6,6,6,6
6,6,6,6,6,6,6,6,6,6,6
6,6,6,6,6,6,6,6,1,6,6
6,6,6,6,6,6,6,6,1,6,6
6,6,1,6,6,6,6,1,1,6,6
6,6,1,1,3,3,3,1,1,6,6
6,6,1,1,3,3,3,1,1,6,6
6,6,1,1,6,3,3,1,1,6,6
6,6,6,1,6,1,1,1,6,6,6
6,6,6,6,6,6,6,6,6,6,6
6,6,6,6,6,6,6,6,6,6,6
endlayer

layer
6,6,6,6,6,6,6,6,6,6,6
6,6,6,6,6,6,6,6,6,6,6
6,6,6,6,6,6,6,6,6,6,6
6,6,6,6,6,6,6,6,6,6,6
6,6,6,6,6,6,6,6,6,6,6
6,6,6,6,6,1,6,6,6,6,6
6,6,6,6,6,1,6,6,6,6,6
6,6,6,6,6,1,6,6,6,6,6
6,6,6,6,6,6,6,6,6,6,6
6,6,6,6,6,6,6,6,6,6,6
6,6,6,6,6,6,6,6,6,6,6
6,6,6,6,6,6,6,6,6,6,6
endlayer

