biomesToSpawnIn=desert,deserthills,beach,ocean,river
weight=1
embed_into_distance=1
acceptable_target_blocks=sand,gravel,clay
dimensions=6,9,8
allowable_overhang=0
max_cut_in=2
cut_in_buffer=1
max_leveling=2
leveling_buffer=1
preserve_water=0
preserve_lava=0
preserve_plants=1


rule1=0,100,sandstone
rule2=0,100,dirt
rule3=0,100,sandstone-2
rule4=0,100,stone_slab-1
rule5=0,100,preserveBlock
rule6=0,100,MobSpawner:Skeleton,MobSpawner:MoCreatures.SilverSkeleton,MobSpawner:MoCreatures.Wraith

layer
1,1,1,1,1,1,1,1
1,2,2,2,2,2,1,1
1,1,1,1,1,1,2,1
1,1,1,1,1,1,2,1
1,1,1,1,1,1,2,1
2,1,1,1,1,1,2,1
2,1,1,1,1,1,2,1
1,2,2,2,2,2,6,1
1,1,1,1,1,1,1,1
endlayer

layer
5,5,5,5,5,5,5,5
5,1,1,1,1,1,5,5
1,5,5,5,5,5,1,5
3,5,5,5,5,5,1,5
5,5,5,5,5,5,1,5
3,5,5,5,5,5,1,5
1,5,5,5,5,5,1,5
5,1,1,1,1,1,5,5
5,5,5,5,5,5,5,5
endlayer

layer
5,5,5,5,5,5,5,5
5,1,5,5,5,1,5,5
5,5,5,5,5,5,1,5
5,5,5,5,5,5,5,5
5,5,5,5,5,5,5,5
5,5,5,5,5,5,5,5
1,5,5,5,5,5,1,5
5,1,5,5,5,1,5,5
5,5,5,5,5,5,5,5
endlayer

layer
5,5,5,5,5,5,5,5
5,5,5,5,5,1,5,5
5,5,5,5,5,5,1,5
5,5,5,5,5,5,5,5
5,5,5,5,5,5,5,5
3,5,5,5,5,5,5,5
1,5,5,5,5,5,1,5
5,1,5,5,5,1,5,5
5,5,5,5,5,5,5,5
endlayer

layer
5,5,5,5,4,4,5,5
5,5,5,5,5,1,4,5
5,5,5,5,1,1,1,4
5,5,5,5,5,1,1,4
5,5,5,5,5,1,1,4
1,1,5,5,5,1,1,4
1,1,1,1,1,1,1,4
4,1,1,1,1,1,4,5
5,4,4,4,4,4,5,5
endlayer

layer
5,5,5,5,5,5,5,5
5,5,5,5,5,5,5,5
5,5,5,4,4,4,5,5
5,5,5,5,1,4,5,5
5,4,5,5,1,4,5,5
5,4,1,1,1,4,5,5
5,4,4,4,4,4,5,5
5,5,5,5,5,5,5,5
5,5,5,5,5,5,5,5
endlayer

