biomesToSpawnIn=extreme hills,extreme hills+,stone beach
weight=20
embed_into_distance=40
acceptable_target_blocks=stone,gravel
dimensions=7,42,19
allowable_overhang=10
max_leveling=1
cut_in_buffer=1
leveling_buffer=1
preserve_water=0
preserve_lava=0
preserve_plants=1
max_cut_in=3
random_height_offset=0,43

rule1=0,100,stone,stone,stone,stone,cobblestone
rule2=0,100,stone,cobblestone
rule3=0,100,MediumMobSpawn,MediumMobSpawn,HardMobSpawn,cobblestone
rule4=0,100,MediumChest,MediumChest,MediumChest,HardChest,dirt,gravel,cobblestone
rule5=0,100,stone,stone,stone,stone,cobblestone,mossy_cobblestone
rule6=0,100,stone_slab
rule7=0,100,log
rule8=0,100,preserveBlock

layer
1,1,1,1,1,1,1,1,1,1,1,1,1,1,1,1,1,1,1
1,1,1,2,2,2,2,2,2,2,2,2,2,2,2,2,1,1,1
1,1,2,2,2,2,2,2,2,2,2,2,2,2,2,2,2,1,1
1,2,2,2,2,2,2,2,2,2,2,2,2,2,2,2,2,2,1
1,2,2,2,2,2,2,2,2,2,2,2,2,2,2,2,2,2,1
1,2,2,2,2,2,2,2,2,2,2,2,2,2,2,2,2,2,1
1,2,2,2,2,2,2,2,2,2,2,2,2,2,2,2,2,2,1
1,2,2,2,2,2,2,2,2,2,2,2,2,2,2,2,2,2,1
1,2,2,2,2,2,2,2,2,2,2,2,2,2,2,2,2,2,1
1,2,2,2,2,2,2,2,2,2,2,2,2,2,2,2,2,2,1
1,2,2,2,2,2,2,2,2,2,2,2,2,2,2,2,2,2,1
1,2,2,2,2,2,2,2,2,2,2,2,2,2,2,2,2,2,1
1,2,2,2,2,2,2,2,2,2,2,2,2,2,2,2,2,2,1
1,2,2,2,2,2,2,2,2,2,2,2,2,2,2,2,2,2,1
1,2,2,2,2,2,2,2,2,2,2,2,2,2,2,2,2,2,1
1,2,2,2,2,2,2,2,2,2,2,2,2,2,2,2,2,2,1
1,2,2,2,2,2,2,2,2,2,2,2,2,2,2,2,2,2,1
1,2,2,2,2,2,2,2,2,2,2,2,2,2,2,2,2,2,1
1,2,2,2,2,3,2,2,2,2,2,2,2,4,2,2,2,2,1
1,2,2,2,2,4,2,2,2,2,2,2,2,3,2,2,2,2,1
1,2,2,2,2,2,2,2,2,2,2,2,2,2,2,2,2,2,1
1,2,2,2,2,2,2,2,2,2,2,2,2,2,2,2,2,2,1
1,2,2,2,2,2,2,2,2,2,2,2,2,2,2,2,2,2,1
1,2,2,2,2,2,2,2,2,2,2,2,2,2,2,2,2,2,1
1,2,2,2,2,2,2,2,2,2,2,2,2,2,2,2,2,2,1
1,2,2,2,2,4,2,2,2,2,2,2,2,3,2,2,2,2,1
1,2,2,2,2,3,2,2,2,2,2,2,2,4,2,2,2,2,1
1,2,2,2,2,2,2,2,2,2,2,2,2,2,2,2,2,2,1
1,2,2,2,2,2,2,2,2,2,2,2,2,2,2,2,2,2,1
1,2,2,2,2,2,2,2,2,2,2,2,2,2,2,2,2,2,1
1,2,2,2,2,2,2,2,2,2,2,2,2,2,2,2,2,2,1
1,2,2,2,2,2,2,2,2,2,2,2,2,2,2,2,2,2,1
1,2,2,2,2,2,2,2,2,2,2,2,2,2,2,2,2,2,1
1,2,2,2,2,2,2,2,2,2,2,2,2,2,2,2,2,2,1
1,2,2,2,2,2,2,2,2,2,2,2,2,2,2,2,2,2,1
1,2,2,2,2,2,2,2,2,2,2,2,2,2,2,2,2,2,1
1,2,2,2,2,2,2,2,2,2,2,2,2,2,2,2,2,2,1
1,2,2,2,2,2,2,2,2,2,2,2,2,2,2,2,2,2,1
1,2,2,2,2,2,2,2,2,2,2,2,2,2,2,2,2,2,1
1,1,2,2,2,2,2,2,2,2,2,2,2,2,2,2,2,1,1
1,1,1,2,2,2,2,2,2,2,2,2,2,2,2,2,1,1,1
1,1,1,1,1,1,1,1,1,1,1,1,1,1,1,1,1,1,1
endlayer

layer
8,8,8,8,8,8,8,8,8,8,8,8,8,8,8,8,8,8,8
8,8,8,1,1,1,1,1,1,1,1,1,1,1,1,1,8,8,8
8,8,1,2,2,2,2,2,2,2,2,2,2,2,2,2,1,8,8
8,1,1,2,2,2,2,2,2,2,2,2,2,2,2,2,1,1,8
8,1,2,2,2,2,2,2,2,2,2,2,2,2,2,2,2,1,8
8,1,2,2,2,2,2,2,2,2,2,2,2,2,2,2,2,1,8
8,1,2,2,2,2,2,2,2,2,2,2,2,2,2,2,2,1,8
8,1,2,2,2,2,2,2,2,2,2,2,2,2,2,2,2,1,8
8,1,2,2,2,2,5,5,5,5,5,5,5,2,2,2,2,1,8
8,1,2,2,2,5,7,0,0,7,0,0,7,5,2,2,2,1,8
8,1,2,2,2,5,0,0,0,0,0,0,0,5,2,2,2,1,8
8,1,2,2,2,5,0,0,0,0,0,0,0,5,2,2,2,1,8
8,1,2,2,2,5,0,0,0,0,0,0,0,5,2,2,2,1,8
8,1,2,2,2,2,5,7,0,0,0,7,5,2,2,2,2,1,8
8,1,2,2,2,2,5,0,0,0,0,0,5,2,2,2,2,1,8
8,1,2,2,2,2,5,0,0,0,0,0,5,2,2,2,2,1,8
8,1,2,2,2,5,5,0,0,0,0,0,5,5,2,2,2,1,8
8,1,2,2,5,0,0,7,0,0,0,7,0,0,5,2,2,1,8
8,1,2,5,5,6,0,0,0,0,0,0,0,6,5,5,2,1,8
8,1,2,5,5,6,0,0,0,0,0,0,0,6,5,5,2,1,8
8,1,2,2,5,0,0,7,0,0,0,7,0,0,5,2,2,1,8
8,1,2,2,2,5,5,0,0,0,0,0,5,5,2,2,2,1,8
8,1,2,2,2,2,5,0,0,0,0,0,5,2,2,2,2,1,8
8,1,2,2,2,5,5,0,0,0,0,0,5,5,2,2,2,1,8
8,1,2,2,5,0,0,7,0,0,0,7,0,0,5,2,2,1,8
8,1,2,5,5,6,0,0,0,0,0,0,0,6,5,5,2,1,8
8,1,2,5,5,6,0,0,0,0,0,0,0,6,5,5,2,1,8
8,1,2,2,5,0,0,7,0,0,0,7,0,0,5,2,2,1,8
8,1,2,2,2,5,5,0,0,0,0,0,5,5,2,2,2,1,8
8,1,2,2,2,2,5,0,0,0,0,0,5,2,2,2,2,1,8
8,1,2,2,2,2,5,0,0,0,0,0,5,2,2,2,2,1,8
8,1,2,2,2,2,5,7,0,0,0,7,5,2,2,2,2,1,8
8,1,2,2,2,5,0,0,0,0,0,0,0,5,2,2,2,1,8
8,1,2,2,2,5,0,0,0,0,0,0,0,5,2,2,2,1,8
8,1,2,2,2,5,0,0,0,0,0,0,0,5,2,2,2,1,8
8,1,2,2,2,5,7,0,0,7,0,0,7,5,2,2,2,1,8
8,1,2,2,2,2,5,5,5,5,5,5,5,2,2,2,2,1,8
8,1,2,2,2,2,2,2,2,2,2,2,2,2,2,2,2,1,8
8,1,1,2,2,2,2,2,2,2,2,2,2,2,2,2,1,1,8
8,8,1,2,2,2,2,2,2,2,2,2,2,2,2,2,1,8,8
8,8,8,1,1,1,1,1,1,1,1,1,1,1,1,1,8,8,8
8,8,8,8,8,8,8,8,8,8,8,8,8,8,8,8,8,8,8
endlayer

layer
8,8,8,8,8,8,8,8,8,8,8,8,8,8,8,8,8,8,8
8,8,8,8,8,8,8,8,8,8,8,8,8,8,8,8,8,8,8
8,8,8,1,1,1,1,1,1,1,1,1,1,1,1,1,8,8,8
8,8,8,1,1,1,1,1,1,1,1,1,1,1,1,1,8,8,8
8,8,1,1,2,2,2,2,2,2,2,2,2,2,2,1,1,8,8
8,8,1,2,2,2,2,2,2,2,2,2,2,2,2,2,1,8,8
8,8,1,2,2,2,2,2,2,2,2,2,2,2,2,2,1,8,8
8,8,1,2,2,2,2,2,2,2,2,2,2,2,2,2,1,8,8
8,8,1,2,2,2,5,5,5,5,5,5,5,2,2,2,1,8,8
8,8,1,2,2,5,7,0,0,7,0,0,7,5,2,2,1,8,8
8,8,1,2,2,5,0,0,0,0,0,0,0,5,2,2,1,8,8
8,8,1,2,2,5,0,0,0,0,0,0,0,5,2,2,1,8,8
8,8,1,2,2,5,0,0,0,0,0,0,0,5,2,2,1,8,8
8,8,1,2,2,2,5,7,0,0,0,7,5,2,2,2,1,8,8
8,8,1,2,2,2,5,0,0,0,0,0,5,2,2,2,1,8,8
8,8,1,2,2,2,5,0,0,0,0,0,5,2,2,2,1,8,8
8,8,1,2,2,5,5,0,0,0,0,0,5,5,2,2,1,8,8
8,8,1,2,5,0,0,7,0,0,0,7,0,0,5,2,1,8,8
8,8,1,5,0,0,0,0,0,0,0,0,0,0,0,5,1,8,8
8,8,1,5,0,0,0,0,0,0,0,0,0,0,0,5,1,8,8
8,8,1,2,5,0,0,7,0,0,0,7,0,0,5,2,1,8,8
8,8,1,2,2,5,5,0,0,0,0,0,5,5,2,2,1,8,8
8,8,1,2,2,2,5,0,0,0,0,0,5,2,2,2,1,8,8
8,8,1,2,2,5,5,0,0,0,0,0,5,5,2,2,1,8,8
8,8,1,2,5,0,0,7,0,0,0,7,0,0,5,2,1,8,8
8,8,1,5,0,0,0,0,0,0,0,0,0,0,0,5,1,8,8
8,8,1,5,0,0,0,0,0,0,0,0,0,0,0,5,1,8,8
8,8,1,2,5,0,0,7,0,0,0,7,0,0,5,2,1,8,8
8,8,1,2,2,5,5,0,0,0,0,0,5,5,2,2,1,8,8
8,8,1,2,2,2,5,0,0,0,0,0,5,2,2,2,1,8,8
8,8,1,2,2,2,5,0,0,0,0,0,5,2,2,2,1,8,8
8,8,1,2,2,2,5,7,0,0,0,7,5,2,2,2,1,8,8
8,8,1,2,2,5,0,0,0,0,0,0,0,5,2,2,1,8,8
8,8,1,2,2,5,0,0,0,0,0,0,0,5,2,2,1,8,8
8,8,1,2,2,5,0,0,0,0,0,0,0,5,2,2,1,8,8
8,8,1,2,2,5,7,0,0,7,0,0,7,5,2,2,1,8,8
8,8,1,2,2,2,5,5,5,5,5,5,5,2,2,2,1,8,8
8,8,1,1,2,2,2,2,2,2,2,2,2,2,2,1,1,8,8
8,8,8,1,1,1,1,1,1,1,1,1,1,1,1,1,8,8,8
8,8,8,1,1,1,1,1,1,1,1,1,1,1,1,1,8,8,8
8,8,8,8,8,8,8,8,8,8,8,8,8,8,8,8,8,8,8
8,8,8,8,8,8,8,8,8,8,8,8,8,8,8,8,8,8,8
endlayer

layer
8,8,8,8,8,8,8,8,8,8,8,8,8,8,8,8,8,8,8
8,8,8,8,8,8,8,8,8,8,8,8,8,8,8,8,8,8,8
8,8,8,8,8,8,8,8,8,8,8,8,8,8,8,8,8,8,8
8,8,8,8,8,8,8,8,8,8,8,8,8,8,8,8,8,8,8
8,8,8,8,1,1,1,1,1,1,1,1,1,1,1,8,8,8,8
8,8,8,1,1,2,2,2,2,2,2,2,2,2,1,1,8,8,8
8,8,8,1,2,2,2,2,2,2,2,2,2,2,2,1,8,8,8
8,8,8,1,2,2,2,2,2,2,2,2,2,2,2,1,8,8,8
8,8,8,1,2,2,2,2,2,2,2,2,2,2,2,1,8,8,8
8,8,8,1,2,2,5,5,5,5,5,5,5,2,2,1,8,8,8
8,8,8,1,2,2,5,5,5,5,5,5,5,2,2,1,8,8,8
8,8,8,1,2,2,5,5,5,5,5,5,5,2,2,1,8,8,8
8,8,8,1,2,2,5,5,5,5,5,5,5,2,2,1,8,8,8
8,8,8,1,2,2,2,5,5,5,5,5,2,2,2,1,8,8,8
8,8,8,1,2,2,2,5,5,5,5,5,2,2,2,1,8,8,8
8,8,8,1,2,2,2,5,5,5,5,5,2,2,2,1,8,8,8
8,8,8,1,2,2,2,5,5,5,5,5,2,2,2,1,8,8,8
8,8,8,1,2,5,5,5,5,5,5,5,5,5,2,1,8,8,8
8,8,8,1,5,5,5,5,5,5,5,5,5,5,5,1,8,8,8
8,8,8,1,5,5,5,5,5,5,5,5,5,5,5,1,8,8,8
8,8,8,1,2,5,5,5,5,5,5,5,5,5,2,1,8,8,8
8,8,8,1,2,2,2,5,5,5,5,5,2,2,2,1,8,8,8
8,8,8,1,2,2,2,5,5,5,5,5,2,2,2,1,8,8,8
8,8,8,1,2,2,2,5,5,5,5,5,2,2,2,1,8,8,8
8,8,8,1,2,5,5,5,5,5,5,5,5,5,2,1,8,8,8
8,8,8,1,5,5,5,5,5,5,5,5,5,5,5,1,8,8,8
8,8,8,1,5,5,5,5,5,5,5,5,5,5,5,1,8,8,8
8,8,8,1,2,5,5,5,5,5,5,5,5,5,2,1,8,8,8
8,8,8,1,2,2,2,5,5,5,5,5,2,2,2,1,8,8,8
8,8,8,1,2,2,2,5,5,5,5,5,2,2,2,1,8,8,8
8,8,8,1,2,2,2,5,5,5,5,5,2,2,2,1,8,8,8
8,8,8,1,2,2,2,5,5,5,5,5,2,2,2,1,8,8,8
8,8,8,1,2,2,5,5,5,5,5,5,5,2,2,1,8,8,8
8,8,8,1,2,2,5,5,5,5,5,5,5,2,2,1,8,8,8
8,8,8,1,2,2,5,5,5,5,5,5,5,2,2,1,8,8,8
8,8,8,1,2,2,5,5,5,5,5,5,5,2,2,1,8,8,8
8,8,8,1,1,2,2,2,2,2,2,2,2,2,1,1,8,8,8
8,8,8,8,1,1,1,1,1,1,1,1,1,1,1,8,8,8,8
8,8,8,8,8,8,8,8,8,8,8,8,8,8,8,8,8,8,8
8,8,8,8,8,8,8,8,8,8,8,8,8,8,8,8,8,8,8
8,8,8,8,8,8,8,8,8,8,8,8,8,8,8,8,8,8,8
8,8,8,8,8,8,8,8,8,8,8,8,8,8,8,8,8,8,8
endlayer

layer
8,8,8,8,8,8,8,8,8,8,8,8,8,8,8,8,8,8,8
8,8,8,8,8,8,8,8,8,8,8,8,8,8,8,8,8,8,8
8,8,8,8,8,8,8,8,8,8,8,8,8,8,8,8,8,8,8
8,8,8,8,8,8,8,8,8,8,8,8,8,8,8,8,8,8,8
8,8,8,8,8,8,8,8,8,8,8,8,8,8,8,8,8,8,8
8,8,8,8,8,1,1,1,1,1,1,1,1,1,8,8,8,8,8
8,8,8,8,1,1,1,1,1,1,1,1,1,1,1,8,8,8,8
8,8,8,8,1,2,2,2,2,2,2,2,2,2,1,8,8,8,8
8,8,8,8,1,2,2,2,2,2,2,2,2,2,1,8,8,8,8
8,8,8,8,1,2,2,2,2,2,2,2,2,2,1,8,8,8,8
8,8,8,8,1,2,2,2,2,2,2,2,2,2,1,8,8,8,8
8,8,8,8,1,2,2,2,2,2,2,2,2,2,1,8,8,8,8
8,8,8,8,1,2,2,2,2,2,2,2,2,2,1,8,8,8,8
8,8,8,8,1,2,2,2,2,2,2,2,2,2,1,8,8,8,8
8,8,8,8,1,2,2,2,2,2,2,2,2,2,1,8,8,8,8
8,8,8,8,1,2,2,2,2,2,2,2,2,2,1,8,8,8,8
8,8,8,8,1,2,2,2,2,2,2,2,2,2,1,8,8,8,8
8,8,8,8,1,2,2,2,2,2,2,2,2,2,1,8,8,8,8
8,8,8,8,1,2,2,2,2,2,2,2,2,2,1,8,8,8,8
8,8,8,8,1,2,2,2,2,2,2,2,2,2,1,8,8,8,8
8,8,8,8,1,2,2,2,2,2,2,2,2,2,1,8,8,8,8
8,8,8,8,1,2,2,2,2,2,2,2,2,2,1,8,8,8,8
8,8,8,8,1,2,2,2,2,2,2,2,2,2,1,8,8,8,8
8,8,8,8,1,2,2,2,2,2,2,2,2,2,1,8,8,8,8
8,8,8,8,1,2,2,2,2,2,2,2,2,2,1,8,8,8,8
8,8,8,8,1,2,2,2,2,2,2,2,2,2,1,8,8,8,8
8,8,8,8,1,2,2,2,2,2,2,2,2,2,1,8,8,8,8
8,8,8,8,1,2,2,2,2,2,2,2,2,2,1,8,8,8,8
8,8,8,8,1,2,2,2,2,2,2,2,2,2,1,8,8,8,8
8,8,8,8,1,2,2,2,2,2,2,2,2,2,1,8,8,8,8
8,8,8,8,1,2,2,2,2,2,2,2,2,2,1,8,8,8,8
8,8,8,8,1,2,2,2,2,2,2,2,2,2,1,8,8,8,8
8,8,8,8,1,2,2,2,2,2,2,2,2,2,1,8,8,8,8
8,8,8,8,1,2,2,2,2,2,2,2,2,2,1,8,8,8,8
8,8,8,8,1,2,2,2,2,2,2,2,2,2,1,8,8,8,8
8,8,8,8,1,1,1,1,1,1,1,1,1,1,1,8,8,8,8
8,8,8,8,8,1,1,1,1,1,1,1,1,1,8,8,8,8,8
8,8,8,8,8,8,8,8,8,8,8,8,8,8,8,8,8,8,8
8,8,8,8,8,8,8,8,8,8,8,8,8,8,8,8,8,8,8
8,8,8,8,8,8,8,8,8,8,8,8,8,8,8,8,8,8,8
8,8,8,8,8,8,8,8,8,8,8,8,8,8,8,8,8,8,8
8,8,8,8,8,8,8,8,8,8,8,8,8,8,8,8,8,8,8
endlayer

layer
8,8,8,8,8,8,8,8,8,8,8,8,8,8,8,8,8,8,8
8,8,8,8,8,8,8,8,8,8,8,8,8,8,8,8,8,8,8
8,8,8,8,8,8,8,8,8,8,8,8,8,8,8,8,8,8,8
8,8,8,8,8,8,8,8,8,8,8,8,8,8,8,8,8,8,8
8,8,8,8,8,8,8,8,8,8,8,8,8,8,8,8,8,8,8
8,8,8,8,8,8,8,8,8,8,8,8,8,8,8,8,8,8,8
8,8,8,8,8,8,8,8,8,8,8,8,8,8,8,8,8,8,8
8,8,8,8,8,1,1,1,1,1,1,1,1,1,8,8,8,8,8
8,8,8,8,8,1,2,2,2,2,2,2,2,1,8,8,8,8,8
8,8,8,8,8,1,2,2,2,2,2,2,2,1,8,8,8,8,8
8,8,8,8,8,1,2,2,2,2,2,2,2,1,8,8,8,8,8
8,8,8,8,8,1,2,2,2,2,2,2,2,1,8,8,8,8,8
8,8,8,8,8,1,2,2,2,2,2,2,2,1,8,8,8,8,8
8,8,8,8,8,1,2,2,2,2,2,2,2,1,8,8,8,8,8
8,8,8,8,8,1,2,2,2,2,2,2,2,1,8,8,8,8,8
8,8,8,8,8,1,2,2,2,2,2,2,2,1,8,8,8,8,8
8,8,8,8,8,1,2,2,2,2,2,2,2,1,8,8,8,8,8
8,8,8,8,8,1,2,2,2,2,2,2,2,1,8,8,8,8,8
8,8,8,8,8,1,2,2,2,2,2,2,2,1,8,8,8,8,8
8,8,8,8,8,1,2,2,2,2,2,2,2,1,8,8,8,8,8
8,8,8,8,8,1,2,2,2,2,2,2,2,1,8,8,8,8,8
8,8,8,8,8,1,2,2,2,2,2,2,2,1,8,8,8,8,8
8,8,8,8,8,1,2,2,2,2,2,2,2,1,8,8,8,8,8
8,8,8,8,8,1,2,2,2,2,2,2,2,1,8,8,8,8,8
8,8,8,8,8,1,2,2,2,2,2,2,2,1,8,8,8,8,8
8,8,8,8,8,1,2,2,2,2,2,2,2,1,8,8,8,8,8
8,8,8,8,8,1,2,2,2,2,2,2,2,1,8,8,8,8,8
8,8,8,8,8,1,2,2,2,2,2,2,2,1,8,8,8,8,8
8,8,8,8,8,1,2,2,2,2,2,2,2,1,8,8,8,8,8
8,8,8,8,8,1,2,2,2,2,2,2,2,1,8,8,8,8,8
8,8,8,8,8,1,2,2,2,2,2,2,2,1,8,8,8,8,8
8,8,8,8,8,1,2,2,2,2,2,2,2,1,8,8,8,8,8
8,8,8,8,8,1,2,2,2,2,2,2,2,1,8,8,8,8,8
8,8,8,8,8,1,2,2,2,2,2,2,2,1,8,8,8,8,8
8,8,8,8,8,1,1,1,1,1,1,1,1,1,8,8,8,8,8
8,8,8,8,8,8,8,8,8,8,8,8,8,8,8,8,8,8,8
8,8,8,8,8,8,8,8,8,8,8,8,8,8,8,8,8,8,8
8,8,8,8,8,8,8,8,8,8,8,8,8,8,8,8,8,8,8
8,8,8,8,8,8,8,8,8,8,8,8,8,8,8,8,8,8,8
8,8,8,8,8,8,8,8,8,8,8,8,8,8,8,8,8,8,8
8,8,8,8,8,8,8,8,8,8,8,8,8,8,8,8,8,8,8
8,8,8,8,8,8,8,8,8,8,8,8,8,8,8,8,8,8,8
endlayer

layer
8,8,8,8,8,8,8,8,8,8,8,8,8,8,8,8,8,8,8
8,8,8,8,8,8,8,8,8,8,8,8,8,8,8,8,8,8,8
8,8,8,8,8,8,8,8,8,8,8,8,8,8,8,8,8,8,8
8,8,8,8,8,8,8,8,8,8,8,8,8,8,8,8,8,8,8
8,8,8,8,8,8,8,8,8,8,8,8,8,8,8,8,8,8,8
8,8,8,8,8,8,8,8,8,8,8,8,8,8,8,8,8,8,8
8,8,8,8,8,8,8,8,8,8,8,8,8,8,8,8,8,8,8
8,8,8,8,8,8,8,8,8,8,8,8,8,8,8,8,8,8,8
8,8,8,8,8,8,1,1,1,1,1,1,1,8,8,8,8,8,8
8,8,8,8,8,8,1,1,1,1,1,1,1,8,8,8,8,8,8
8,8,8,8,8,8,1,1,1,1,1,1,1,8,8,8,8,8,8
8,8,8,8,8,8,1,1,1,1,1,1,1,8,8,8,8,8,8
8,8,8,8,8,8,1,1,1,1,1,1,1,8,8,8,8,8,8
8,8,8,8,8,8,1,1,1,1,1,1,1,8,8,8,8,8,8
8,8,8,8,8,8,1,1,1,1,1,1,1,8,8,8,8,8,8
8,8,8,8,8,8,1,1,1,1,1,1,1,8,8,8,8,8,8
8,8,8,8,8,8,1,1,1,1,1,1,1,8,8,8,8,8,8
8,8,8,8,8,8,1,1,1,1,1,1,1,8,8,8,8,8,8
8,8,8,8,8,8,1,1,1,1,1,1,1,8,8,8,8,8,8
8,8,8,8,8,8,1,1,1,1,1,1,1,8,8,8,8,8,8
8,8,8,8,8,8,1,1,1,1,1,1,1,8,8,8,8,8,8
8,8,8,8,8,8,1,1,1,1,1,1,1,8,8,8,8,8,8
8,8,8,8,8,8,1,1,1,1,1,1,1,8,8,8,8,8,8
8,8,8,8,8,8,1,1,1,1,1,1,1,8,8,8,8,8,8
8,8,8,8,8,8,1,1,1,1,1,1,1,8,8,8,8,8,8
8,8,8,8,8,8,1,1,1,1,1,1,1,8,8,8,8,8,8
8,8,8,8,8,8,1,1,1,1,1,1,1,8,8,8,8,8,8
8,8,8,8,8,8,1,1,1,1,1,1,1,8,8,8,8,8,8
8,8,8,8,8,8,1,1,1,1,1,1,1,8,8,8,8,8,8
8,8,8,8,8,8,1,1,1,1,1,1,1,8,8,8,8,8,8
8,8,8,8,8,8,1,1,1,1,1,1,1,8,8,8,8,8,8
8,8,8,8,8,8,1,1,1,1,1,1,1,8,8,8,8,8,8
8,8,8,8,8,8,1,1,1,1,1,1,1,8,8,8,8,8,8
8,8,8,8,8,8,1,1,1,1,1,1,1,8,8,8,8,8,8
8,8,8,8,8,8,8,8,8,8,8,8,8,8,8,8,8,8,8
8,8,8,8,8,8,8,8,8,8,8,8,8,8,8,8,8,8,8
8,8,8,8,8,8,8,8,8,8,8,8,8,8,8,8,8,8,8
8,8,8,8,8,8,8,8,8,8,8,8,8,8,8,8,8,8,8
8,8,8,8,8,8,8,8,8,8,8,8,8,8,8,8,8,8,8
8,8,8,8,8,8,8,8,8,8,8,8,8,8,8,8,8,8,8
8,8,8,8,8,8,8,8,8,8,8,8,8,8,8,8,8,8,8
8,8,8,8,8,8,8,8,8,8,8,8,8,8,8,8,8,8,8
endlayer

