
weight=1
embed_into_distance=9
acceptable_target_blocks=stone,grass,dirt,sand,gravel,sandstone,cobblestone
dimensions=24,9,9
cut_in_buffer=1
max_leveling=1
leveling_buffer=0
preserve_water=1
preserve_lava=1
preserve_plants=1
max_cut_in=5
random_height_offset=0,7

# preserve the surroundings
rule1=0,100,preserveBlock

# always print this nether brick
rule2=0,100,nether_brick

# occasionally print this quartz shard
rule3=0,100,quartz_block

# always print this quartz of there is one below
rule4=0,100,quartz_block,quartz_block,quartz_block,quartz_block,quartz_block,quartz_block,MobSpawner:Blaze

# always print this quartz if there is one to the side
rule5=2,100,quartz_block

# always print this netherrack if there is something below
rule6=1,100,netherrack

# always print this netherbrick fence if there's a block below
rule7=1,100,nether_brick_fence

# always print this flame if there's a block below
rule8=1,100,fire

# occasionally print this flame if there's a block below
rule9=1,25,fire

# always print a mobspawner of a hellish sort
rule10=0,100,MobSpawner:Blaze,MobSpawner:Blaze,MobSpawner:Blaze,MobSpawner:Blaze,MobSpawner:Blaze,MobSpawner:Blaze,MobSpawner:Blaze,MobSpawner:Blaze,MobSpawner:Blaze,MobSpawner:Blaze,MobSpawner:Blaze,MobSpawner:Blaze,MobSpawner:Blaze,MobSpawner:Blaze,MobSpawner:Ghast

# 1: base layer and spawner
layer
1,1,1,1,1,1,1,1,1
1,1,1,1,1,1,1,1,1
1,1,1,6,2,6,1,1,1
1,1,6,6,6,6,6,1,1
1,1,2,6,10,6,2,1,1
1,1,6,6,6,6,6,1,1
1,1,1,6,2,6,1,1,1
1,1,1,1,1,1,1,1,1
1,1,1,1,1,1,1,1,1
endlayer

# 2: base layer with firy crater
layer
1,1,1,1,6,1,1,1,1
1,1,1,1,6,1,1,1,1
1,1,1,6,2,6,1,1,1
1,1,6,9,9,9,6,1,1
6,6,2,9,9,9,2,6,6
1,1,6,9,9,9,6,1,1
1,1,1,6,2,6,1,1,1
1,1,1,1,6,1,1,1,1
1,1,1,1,6,1,1,1,1
endlayer

# 3: top of netherack minicrater and flames
layer
1,1,1,1,9,1,1,1,1
1,1,1,1,6,1,1,1,1
1,1,1,9,2,9,1,1,1
1,1,9,0,0,0,9,1,1
9,6,2,0,0,0,2,6,9
1,1,9,0,0,0,9,1,1
1,1,1,9,2,9,1,1,1
1,1,1,1,6,1,1,1,1
1,1,1,1,9,1,1,1,1
endlayer

# 4: crater hole and some flames and netherbrick legs
layer
1,1,1,1,1,1,1,1,1
1,1,1,1,9,1,1,1,1
1,1,1,0,2,0,1,1,1
1,1,0,0,0,0,0,1,1
1,9,2,0,0,0,2,9,1
1,1,0,0,0,0,0,1,1
1,1,1,0,2,0,1,1,1
1,1,1,1,9,1,1,1,1
1,1,1,1,1,1,1,1,1
endlayer

# 5: crater hole and netherbrick legs
layer
1,1,1,1,1,1,1,1,1
1,1,1,0,0,0,1,1,1
1,1,0,0,2,0,0,1,1
1,0,0,0,0,0,0,0,1
1,0,2,0,0,0,2,0,1
1,0,0,0,0,0,0,0,1
1,1,0,0,2,0,0,1,1
1,1,1,0,0,0,1,1,1
1,1,1,1,1,1,1,1,1
endlayer

# 6: crater hole and netherbrick legs
layer
1,1,1,1,1,1,1,1,1
1,1,1,0,0,0,1,1,1
1,1,0,0,2,0,0,1,1
1,0,0,0,0,0,0,0,1
1,0,2,0,0,0,2,0,1
1,0,0,0,0,0,0,0,1
1,1,0,0,2,0,0,1,1
1,1,1,0,0,0,1,1,1
1,1,1,1,1,1,1,1,1
endlayer

# 7: crater hole and netherbrick legs
layer
1,1,1,0,0,0,1,1,1
1,1,0,0,0,0,0,1,1
1,0,0,0,2,0,0,0,1
0,0,0,0,0,0,0,0,0
0,0,2,0,0,0,2,0,0
0,0,0,0,0,0,0,0,0
1,0,0,0,2,0,0,0,1
1,1,0,0,0,0,0,1,1
1,1,1,0,0,0,1,1,1
endlayer

# 8: crater top and netherbrick arches
layer
1,1,0,0,0,0,0,1,1
1,0,0,0,0,0,0,0,1
0,0,0,2,2,2,0,0,0
0,0,2,0,0,0,2,0,0
0,0,2,0,0,0,2,0,0
0,0,2,0,0,0,2,0,0
0,0,0,2,2,2,0,0,0
1,0,0,0,0,0,0,0,1
1,1,0,0,0,0,0,1,1
endlayer

# 9: crater top and netherbrick arches
layer
1,0,0,0,0,0,0,0,1
0,0,0,0,0,0,0,0,0
0,0,2,2,2,2,2,0,0
0,0,2,2,0,2,2,0,0
0,0,2,0,0,0,2,0,0
0,0,2,2,0,2,2,0,0
0,0,2,2,2,2,2,0,0
0,0,0,0,0,0,0,0,0
1,0,0,0,0,0,0,0,1
endlayer

# 10: crater top and netherbrick ring
layer
0,0,0,0,0,0,0,0,0
0,0,0,2,2,2,0,0,0
0,0,2,2,2,2,2,0,0
0,2,2,2,0,2,2,2,0
0,2,2,0,0,0,2,2,0
0,2,2,2,0,2,2,2,0
0,0,2,2,2,2,2,0,0
0,0,0,2,2,2,0,0,0
0,0,0,0,0,0,0,0,0
endlayer

# 11: netherbrick plate and netherrack ring
layer
0,0,0,2,2,2,0,0,0
0,2,2,6,6,6,2,2,0
0,2,6,2,2,2,6,2,0
2,6,2,2,2,2,2,6,2
2,6,2,2,0,2,2,6,2
2,6,2,2,2,2,2,6,2
0,2,6,2,2,2,6,2,0
0,2,2,6,6,6,2,2,0
0,0,0,2,2,2,0,0,0
endlayer

# 12: ring of flames and inner netherbrick ring
layer
0,0,0,0,0,0,0,0,0
0,0,0,8,8,8,0,0,0
0,0,8,2,2,2,8,0,0
0,8,2,0,0,0,2,8,0
0,8,2,0,0,0,2,8,0
0,8,2,0,0,0,2,8,0
0,0,8,2,2,2,8,0,0
0,0,0,8,8,8,0,0,0
0,0,0,0,0,0,0,0,0
endlayer

# 13: upper pylons
layer
0,0,0,0,0,0,0,0,0
0,0,0,0,0,0,0,0,0
0,0,0,0,2,0,0,0,0
0,0,0,0,0,0,0,0,0
0,0,2,0,0,0,2,0,0
0,0,0,0,0,0,0,0,0
0,0,0,0,2,0,0,0,0
0,0,0,0,0,0,0,0,0
0,0,0,0,0,0,0,0,0
endlayer

# 14: ring of flames and inner netherbrick ring
layer
0,0,0,0,0,0,0,0,0
0,0,0,0,0,0,0,0,0
0,0,0,0,7,0,0,0,0
0,0,0,0,0,0,0,0,0
0,0,7,0,0,0,7,0,0
0,0,0,0,0,0,0,0,0
0,0,0,0,7,0,0,0,0
0,0,0,0,0,0,0,0,0
0,0,0,0,0,0,0,0,0
endlayer

# 15: empty space
layer
0,0,0,0,0,0,0,0,0
0,0,0,0,0,0,0,0,0
0,0,0,0,0,0,0,0,0
0,0,0,0,0,0,0,0,0
0,0,0,0,0,0,0,0,0
0,0,0,0,0,0,0,0,0
0,0,0,0,0,0,0,0,0
0,0,0,0,0,0,0,0,0
0,0,0,0,0,0,0,0,0
endlayer

# 16: empty space
layer
0,0,0,0,0,0,0,0,0
0,0,0,0,0,0,0,0,0
0,0,0,0,0,0,0,0,0
0,0,0,0,0,0,0,0,0
0,0,0,0,0,0,0,0,0
0,0,0,0,0,0,0,0,0
0,0,0,0,0,0,0,0,0
0,0,0,0,0,0,0,0,0
0,0,0,0,0,0,0,0,0
endlayer

# 17: empty space
layer
0,0,0,0,0,0,0,0,0
0,0,0,0,0,0,0,0,0
0,0,0,0,0,0,0,0,0
0,0,0,0,0,0,0,0,0
0,0,0,0,0,0,0,0,0
0,0,0,0,0,0,0,0,0
0,0,0,0,0,0,0,0,0
0,0,0,0,0,0,0,0,0
0,0,0,0,0,0,0,0,0
endlayer

# 18: empty space
layer
0,0,0,0,0,0,0,0,0
0,0,0,0,0,0,0,0,0
0,0,0,0,0,0,0,0,0
0,0,0,0,0,0,0,0,0
0,0,0,0,0,0,0,0,0
0,0,0,0,0,0,0,0,0
0,0,0,0,0,0,0,0,0
0,0,0,0,0,0,0,0,0
0,0,0,0,0,0,0,0,0
endlayer

# 19: conditional quartz shard
layer
0,0,0,0,0,0,0,0,0
0,0,0,0,0,0,0,0,0
0,0,0,0,0,0,0,0,0
0,0,0,0,0,0,0,0,0
0,0,0,0,3,0,0,0,0
0,0,0,0,0,0,0,0,0
0,0,0,0,0,0,0,0,0
0,0,0,0,0,0,0,0,0
0,0,0,0,0,0,0,0,0
endlayer

# 20: conditional quartz shard
layer
0,0,0,0,0,0,0,0,0
0,0,0,0,0,0,0,0,0
0,0,0,0,0,0,0,0,0
0,0,0,0,0,0,0,0,0
0,0,0,0,3,0,0,0,0
0,0,0,0,0,0,0,0,0
0,0,0,0,0,0,0,0,0
0,0,0,0,0,0,0,0,0
0,0,0,0,0,0,0,0,0
endlayer

# 21: conditional quartz shard and spawner
layer
0,0,0,0,0,0,0,0,0
0,0,0,0,0,0,0,0,0
0,0,0,0,0,0,0,0,0
0,0,0,0,3,0,0,0,0
0,0,0,3,4,3,0,0,0
0,0,0,0,3,0,0,0,0
0,0,0,0,0,0,0,0,0
0,0,0,0,0,0,0,0,0
0,0,0,0,0,0,0,0,0
endlayer

# 22: conditional quartz shard
layer
0,0,0,0,0,0,0,0,0
0,0,0,0,0,0,0,0,0
0,0,0,0,0,0,0,0,0
0,0,0,0,0,0,0,0,0
0,0,0,0,3,0,0,0,0
0,0,0,0,0,0,0,0,0
0,0,0,0,0,0,0,0,0
0,0,0,0,0,0,0,0,0
0,0,0,0,0,0,0,0,0
endlayer

# 23: conditional quartz shard
layer
0,0,0,0,0,0,0,0,0
0,0,0,0,0,0,0,0,0
0,0,0,0,0,0,0,0,0
0,0,0,0,0,0,0,0,0
0,0,0,0,3,0,0,0,0
0,0,0,0,0,0,0,0,0
0,0,0,0,0,0,0,0,0
0,0,0,0,0,0,0,0,0
0,0,0,0,0,0,0,0,0
endlayer

# 24: conditional quartz shard
layer
0,0,0,0,0,0,0,0,0
0,0,0,0,0,0,0,0,0
0,0,0,0,0,0,0,0,0
0,0,0,0,0,0,0,0,0
0,0,0,0,3,0,0,0,0
0,0,0,0,0,0,0,0,0
0,0,0,0,0,0,0,0,0
0,0,0,0,0,0,0,0,0
0,0,0,0,0,0,0,0,0
endlayer



