weight=25
embed_into_distance=3
acceptable_target_blocks=stone,grass,dirt,sand,gravel
dimensions=6,25,25
allowable_overhang=0
max_cut_in=1
cut_in_buffer=3
max_leveling=0
leveling_buffer=0
preserve_water=1
preserve_lava=1
preserve_plants=1
random_height_offset=-2,0

rule1=0,100,preserveBlock
rule2=0,100,preserveBlock,preserveBlock,stone
rule3=0,100,preserveBlock,preserveBlock,preserveBlock,preserveBlock,obsidian
rule4=0,100,preserveBlock,preserveBlock,preserveBlock,gravel
rule5=0,20,preserveBlock,preserveBlock,preserveBlock,gravel
rule6=0,100,preserveBlock,air,air
rule7=0,100,preserveBlock

layer
1,1,1,1,1,1,1,1,1,1,1,1,1,1,1,1,1,1,1,1,1,1,1,1,1
1,1,1,1,1,1,1,1,1,1,1,1,1,1,1,1,1,1,1,1,1,1,1,1,1
1,1,1,1,1,1,1,1,1,1,1,1,1,1,1,1,1,1,1,1,1,1,1,1,1
1,1,1,1,1,1,1,1,1,1,1,1,1,1,1,1,1,1,1,1,1,1,1,1,1
1,1,1,1,1,1,1,1,1,1,1,1,1,1,1,1,1,1,1,1,1,1,1,1,1
1,1,1,1,1,1,1,1,1,1,1,1,1,1,1,1,1,1,1,1,1,1,1,1,1
1,1,1,1,1,1,1,1,1,1,1,1,1,1,1,1,1,1,1,1,1,1,1,1,1
1,1,1,1,1,1,1,1,1,1,2,2,2,2,2,1,1,1,1,1,1,1,1,1,1
1,1,1,1,1,1,1,1,1,2,2,3,3,3,2,2,1,1,1,1,1,1,1,1,1
1,1,1,1,1,1,1,1,2,3,3,3,3,3,3,2,2,1,1,1,1,1,1,1,1
1,1,1,1,1,1,1,2,2,3,3,3,3,3,3,3,2,1,1,1,1,1,1,1,1
1,1,1,1,1,1,1,2,2,3,3,3,3,3,3,3,2,1,1,1,1,1,1,1,1
1,1,1,1,1,1,1,2,2,3,3,3,3,3,3,3,2,2,1,1,1,1,1,1,1
1,1,1,1,1,1,1,2,2,3,3,3,3,3,3,3,2,2,1,1,1,1,1,1,1
1,1,1,1,1,1,1,1,2,2,3,3,3,3,3,3,2,1,1,1,1,1,1,1,1
1,1,1,1,1,1,1,1,1,2,3,3,3,3,3,2,2,1,1,1,1,1,1,1,1
1,1,1,1,1,1,1,1,1,1,2,2,3,3,2,2,1,1,1,1,1,1,1,1,1
1,1,1,1,1,1,1,1,1,1,1,2,2,2,2,1,1,1,1,1,1,1,1,1,1
1,1,1,1,1,1,1,1,1,1,1,1,1,1,1,1,1,1,1,1,1,1,1,1,1
1,1,1,1,1,1,1,1,1,1,1,1,1,1,1,1,1,1,1,1,1,1,1,1,1
1,1,1,1,1,1,1,1,1,1,1,1,1,1,1,1,1,1,1,1,1,1,1,1,1
1,1,1,1,1,1,1,1,1,1,1,1,1,1,1,1,1,1,1,1,1,1,1,1,1
1,1,1,1,1,1,1,1,1,1,1,1,1,1,1,1,1,1,1,1,1,1,1,1,1
1,1,1,1,1,1,1,1,1,1,1,1,1,1,1,1,1,1,1,1,1,1,1,1,1
1,1,1,1,1,1,1,1,1,1,1,1,1,1,1,1,1,1,1,1,1,1,1,1,1
endlayer


layer
1,1,1,1,1,1,1,1,1,1,1,1,1,1,1,1,1,1,1,1,1,1,1,1,1
1,1,1,1,1,1,1,1,1,1,1,1,1,1,1,1,1,1,1,1,1,1,1,1,1
1,1,1,1,1,1,1,1,1,1,1,1,1,1,1,1,1,1,1,1,1,1,1,1,1
1,1,1,1,1,1,1,1,4,4,2,2,2,2,4,4,1,1,1,1,1,1,1,1,1
1,1,1,1,1,1,1,4,2,2,2,2,2,2,2,2,2,4,1,1,1,1,1,1,1
1,1,1,1,1,1,4,2,2,2,2,2,2,2,2,2,2,2,4,1,1,1,1,1,1
1,1,1,1,1,4,2,2,2,2,2,5,5,5,2,2,2,2,2,4,1,1,1,1,1
1,1,1,1,4,2,2,2,2,5,5,5,5,5,5,2,2,2,2,2,1,1,1,1,1
1,1,1,4,2,2,2,2,5,5,5,5,5,5,5,5,2,2,2,2,4,1,1,1,1
1,1,1,4,2,2,2,5,5,5,5,3,3,5,5,5,5,2,2,2,4,1,1,1,1
1,1,1,4,2,2,2,5,5,5,3,3,3,3,5,5,5,5,2,2,4,1,1,1,1
1,1,1,4,2,2,2,5,5,5,3,3,3,3,3,5,5,5,2,2,2,1,1,1,1
1,1,1,4,2,2,2,5,5,5,3,3,6,3,3,5,5,5,2,2,2,4,1,1,1
1,1,1,4,2,2,2,5,5,5,3,3,3,3,3,5,5,5,2,2,2,4,1,1,1
1,1,1,4,2,2,2,2,5,5,5,3,3,3,3,5,5,5,2,2,2,4,1,1,1
1,1,1,1,4,2,2,2,5,5,5,5,3,5,5,5,5,5,2,2,2,4,1,1,1
1,1,1,1,4,2,2,2,2,5,5,5,5,5,5,5,5,2,2,2,2,4,1,1,1
1,1,1,1,1,4,2,2,2,2,5,5,5,5,5,5,2,2,2,2,4,1,1,1,1
1,1,1,1,1,1,4,2,2,2,2,2,5,2,2,2,2,2,2,4,1,1,1,1,1
1,1,1,1,1,1,1,4,2,2,2,2,2,2,2,2,2,2,4,1,1,1,1,1,1
1,1,1,1,1,1,1,1,4,2,2,2,2,2,2,2,4,4,1,1,1,1,1,1,1
1,1,1,1,1,1,1,1,1,4,4,2,2,2,4,4,1,1,1,1,1,1,1,1,1
1,1,1,1,1,1,1,1,1,1,1,1,1,1,1,1,1,1,1,1,1,1,1,1,1
1,1,1,1,1,1,1,1,1,1,1,1,1,1,1,1,1,1,1,1,1,1,1,1,1
1,1,1,1,1,1,1,1,1,1,1,1,1,1,1,1,1,1,1,1,1,1,1,1,1
endlayer


layer
1,1,1,1,1,1,1,1,1,1,1,1,1,1,1,1,1,1,1,1,1,1,1,1,1
1,1,1,1,1,1,1,1,1,1,1,1,1,1,1,1,1,1,1,1,1,1,1,1,1
1,1,1,1,1,1,1,1,1,1,4,2,2,2,4,1,1,1,1,1,1,1,1,1,1
1,1,1,1,1,1,1,4,4,2,2,2,2,2,2,4,4,4,1,1,1,1,1,1,1
1,1,1,1,1,1,4,2,2,0,0,0,0,0,0,2,2,2,4,1,1,1,1,1,1
1,1,1,1,1,4,2,2,0,0,0,0,0,0,0,0,0,2,2,2,1,1,1,1,1
1,1,1,4,2,2,0,0,0,0,0,0,0,0,0,0,0,0,2,2,4,1,1,1,1
1,1,1,2,2,0,0,0,0,0,0,0,0,0,0,0,0,0,0,2,4,1,1,1,1
1,1,4,2,2,0,0,0,0,0,0,0,0,0,0,0,0,0,0,2,2,1,1,1,1
1,1,4,2,0,0,0,0,0,0,0,0,0,0,0,0,0,0,0,0,2,4,1,1,1
1,1,4,2,0,0,0,0,0,0,0,0,0,0,0,0,0,0,0,0,2,4,1,1,1
1,1,4,2,0,0,0,0,0,0,0,2,2,0,0,0,0,0,0,0,2,4,1,1,1
1,1,1,2,0,0,0,0,0,0,0,2,6,2,0,0,0,0,0,0,2,2,1,1,1
1,1,4,2,2,0,0,0,0,0,0,0,2,0,0,0,0,0,0,0,2,2,1,1,1
1,1,1,2,2,0,0,0,0,0,0,0,0,0,0,0,0,0,0,0,0,2,1,1,1
1,1,1,4,2,0,0,0,0,0,0,0,0,0,0,0,0,0,0,0,2,2,1,1,1
1,1,1,1,4,2,0,0,0,0,0,0,0,0,0,0,0,0,0,0,2,2,1,1,1
1,1,1,1,1,2,2,0,0,0,0,0,0,0,0,0,0,0,0,2,2,4,1,1,1
1,1,1,1,1,4,2,0,0,0,0,0,0,0,0,0,0,0,2,2,2,1,1,1,1
1,1,1,1,1,1,2,2,0,0,0,0,0,0,0,0,0,2,2,4,1,1,1,1,1
1,1,1,1,1,1,4,2,2,2,0,0,0,0,0,2,2,4,4,1,1,1,1,1,1
1,1,1,1,1,1,1,4,2,2,2,2,2,2,2,2,4,1,1,1,1,1,1,1,1
1,1,1,1,1,1,1,1,1,1,4,4,4,4,4,1,1,1,1,1,1,1,1,1,1
1,1,1,1,1,1,1,1,1,1,1,1,1,1,1,1,1,1,1,1,1,1,1,1,1
1,1,1,1,1,1,1,1,1,1,1,1,1,1,1,1,1,1,1,1,1,1,1,1,1
endlayer


layer
1,1,1,1,1,1,1,1,7,1,7,7,1,7,1,1,1,1,1,1,1,1,1,1,1
1,1,7,1,1,1,1,7,4,4,7,4,4,7,1,7,1,1,7,7,1,1,1,1,1
1,1,1,7,7,7,1,7,4,7,2,2,0,2,7,7,7,7,4,7,1,1,1,1,1
1,1,1,7,4,7,7,7,2,2,0,0,0,0,2,2,2,4,4,7,1,1,1,1,1
1,7,1,1,7,4,2,0,0,0,0,0,0,0,0,0,0,0,2,7,7,7,7,1,1
1,1,7,7,7,2,0,0,0,0,0,0,0,0,0,0,0,0,0,2,4,4,7,1,1
1,1,7,4,2,0,0,0,0,0,0,0,0,0,0,0,0,0,0,0,2,7,7,1,1
1,7,7,2,0,0,0,0,0,0,0,0,0,0,0,0,0,0,0,0,2,4,7,1,1
1,1,2,0,0,0,0,0,0,0,0,0,0,0,0,0,0,0,0,0,2,7,4,1,1
1,7,2,0,0,0,0,0,0,0,0,0,0,0,0,0,0,0,0,0,0,2,4,7,1
7,4,2,0,0,0,0,0,0,0,0,0,0,0,0,0,0,0,0,0,0,2,4,7,1
1,7,7,0,0,0,0,0,0,0,0,0,0,0,0,0,0,0,0,0,0,2,4,4,7
7,7,7,0,0,0,0,0,0,0,0,0,6,0,0,0,0,0,0,0,0,2,7,7,1
1,7,2,0,0,0,0,0,0,0,0,0,0,0,0,0,0,0,0,0,0,0,7,7,1
7,7,7,2,0,0,0,0,0,0,0,0,0,0,0,0,0,0,0,0,0,2,7,1,1
1,1,4,2,2,0,0,0,0,0,0,0,0,0,0,0,0,0,0,0,0,2,7,7,1
7,7,7,4,2,0,0,0,0,0,0,0,0,0,0,0,0,0,0,0,0,2,7,7,1
1,1,1,7,7,2,0,0,0,0,0,0,0,0,0,0,0,0,0,0,0,2,7,7,1
1,1,1,7,1,2,0,0,0,0,0,0,0,0,0,0,0,0,0,0,2,7,7,1,1
1,1,1,1,1,7,2,0,0,0,0,0,0,0,0,0,0,0,0,2,7,1,7,1,1
1,1,1,7,7,7,7,2,0,0,0,0,0,0,0,0,0,2,2,4,7,1,1,1,1
1,7,1,1,7,1,7,4,2,0,0,0,0,0,0,2,4,4,4,7,7,7,1,1,1
1,1,7,1,1,1,7,7,7,4,2,2,2,4,4,4,4,7,7,1,1,7,1,1,1
1,1,1,1,1,7,1,1,1,7,7,7,1,7,4,4,7,1,1,7,1,1,1,1,1
1,1,1,1,1,1,1,1,1,7,1,7,1,1,1,7,1,1,1,1,1,1,1,1,1
endlayer


layer
1,1,1,1,1,1,1,1,7,1,7,7,0,7,0,1,1,1,1,1,1,1,1,1,1
1,1,7,1,1,1,0,2,7,7,7,2,7,2,0,7,1,1,7,7,1,1,1,1,1
1,1,1,7,7,2,0,7,7,2,0,2,2,0,0,7,7,7,7,7,1,1,1,1,1
1,1,1,7,7,7,0,2,2,0,0,0,0,0,0,0,2,2,7,7,1,1,1,1,1
1,7,1,1,7,7,0,0,0,0,0,0,0,0,0,0,0,2,2,7,7,7,7,1,1
1,1,7,7,7,2,0,0,0,0,0,0,0,0,0,0,0,0,0,2,2,7,7,1,1
1,1,7,7,2,0,0,0,0,0,0,0,0,0,0,0,0,0,0,0,0,2,7,1,1
1,7,2,2,0,0,0,0,0,0,0,0,0,0,0,0,0,0,0,0,2,7,7,1,1
1,0,0,0,0,0,0,0,0,0,0,0,0,0,0,0,0,0,0,0,2,7,7,1,1
1,2,0,0,0,0,0,0,0,0,0,0,0,0,0,0,0,0,0,0,0,0,2,7,1
7,7,2,0,0,0,0,0,0,0,0,0,0,0,0,0,0,0,0,0,0,2,7,7,1
1,7,7,0,0,0,0,0,0,0,0,0,0,0,0,0,0,0,0,0,2,2,2,7,7
7,7,7,0,0,0,0,0,0,0,0,0,6,0,0,0,0,0,0,0,0,0,7,7,1
1,7,2,0,0,0,0,0,0,0,0,0,0,0,0,0,0,0,0,0,0,0,2,7,1
7,7,2,0,0,0,0,0,0,0,0,0,0,0,0,0,0,0,0,0,0,0,0,0,1
1,1,7,2,0,0,0,0,0,0,0,0,0,0,0,0,0,0,0,0,0,0,2,2,1
7,7,7,7,2,0,0,0,0,0,0,0,0,0,0,0,0,0,0,0,0,0,2,7,1
1,1,1,7,7,0,0,0,0,0,0,0,0,0,0,0,0,0,0,0,0,2,2,7,1
1,1,1,7,0,0,0,0,0,0,0,0,0,0,0,0,0,0,0,0,0,7,7,1,1
1,1,1,1,0,2,0,0,0,0,0,0,0,0,0,0,0,0,0,2,0,0,7,1,1
1,1,1,7,7,7,2,2,0,0,0,0,0,0,0,0,0,2,7,7,2,1,1,1,1
1,7,1,1,7,1,7,2,2,2,0,0,0,0,2,2,2,7,2,7,7,7,1,1,1
1,1,7,1,1,1,7,7,7,7,2,0,2,7,2,7,7,7,7,1,1,7,1,1,1
1,1,1,1,1,7,1,1,1,7,7,7,0,7,2,7,7,1,1,7,1,1,1,1,1
1,1,1,1,1,1,1,1,1,7,1,7,1,1,1,7,1,1,1,1,1,1,1,1,1
endlayer


layer
1,1,1,1,1,1,1,1,1,1,1,1,1,1,1,1,1,1,1,1,1,1,1,1,1
1,1,1,1,1,1,1,1,1,7,1,7,1,1,1,1,1,1,1,1,1,1,1,1,1
1,1,1,1,0,1,1,7,7,0,0,0,0,0,0,0,0,0,0,1,1,1,1,1,1
1,1,1,1,7,7,0,0,2,0,0,0,0,0,0,0,2,7,0,1,1,1,1,1,1
1,1,1,1,1,7,0,0,0,0,0,0,0,0,0,0,0,0,7,1,1,1,1,1,1
1,1,1,1,0,7,0,0,0,0,0,0,0,0,0,0,0,0,0,2,7,0,1,1,1
1,1,1,7,7,0,0,0,0,0,0,0,0,0,0,0,0,0,0,0,0,0,1,1,1
1,0,2,0,0,0,0,0,0,0,0,0,0,0,0,0,0,0,0,0,2,0,1,1,1
1,0,0,0,0,0,0,0,0,0,0,0,0,0,0,0,0,0,0,0,0,0,0,1,1
1,1,0,0,0,0,0,0,0,0,0,0,0,0,0,0,0,0,0,0,0,0,7,1,1
1,7,0,0,0,0,0,0,0,0,0,0,0,0,0,0,0,0,0,0,0,0,0,1,1
1,1,2,0,0,0,0,0,0,0,0,0,0,0,0,0,0,0,0,0,0,2,7,1,1
1,1,0,0,0,0,0,0,0,0,0,0,0,0,0,0,0,0,0,0,0,0,7,1,1
1,0,0,0,0,0,0,0,0,0,0,0,0,0,0,0,0,0,0,0,0,0,0,0,1
1,1,0,0,0,0,0,0,0,0,0,0,0,0,0,0,0,0,0,0,0,0,0,0,1
1,1,0,2,0,0,0,0,0,0,0,0,0,0,0,0,0,0,0,0,0,0,0,7,1
1,1,1,0,2,0,0,0,0,0,0,0,0,0,0,0,0,0,0,0,0,0,0,1,1
1,1,1,1,7,0,0,0,0,0,0,0,0,0,0,0,0,0,0,0,0,0,0,1,1
1,1,1,1,1,0,0,0,0,0,0,0,0,0,0,0,0,0,0,0,0,0,1,1,1
1,1,1,1,1,0,0,0,0,0,0,0,0,0,0,0,0,0,0,2,0,1,1,1,1
1,1,1,1,0,1,0,0,0,0,0,0,0,0,0,0,0,0,2,7,7,1,1,1,1
1,1,1,1,1,1,1,0,0,0,0,0,0,0,0,0,7,7,7,0,1,1,1,1,1
1,1,1,1,1,1,1,1,0,0,7,0,0,7,0,7,0,1,1,1,1,1,1,1,1
1,1,1,1,1,1,1,1,1,0,0,7,1,0,7,0,1,1,1,1,1,1,1,1,1
1,1,1,1,1,1,1,1,1,1,1,1,1,1,1,1,1,1,1,1,1,1,1,1,1
endlayer

