biomesToSpawnIn=birch forest,birch forest hills,birch forest hills m,birch forest m,boreal forest,brushland,chaparral,cherry blossom grove,cold taiga,cold taiga hills,cold taiga m,coniferous forest,dead forest,deciduous forest,desert,desert m,deserthills,dunes,extreme hills edge,fen,flower field,flower forest,forest,foresthills,grassland,grove,heathland,highland,lavender fields,lush desert,lush swamp,maple woods,marsh,meadow,mega spruce taiga,mega taiga,mega taiga hills,mesa plateau f,mesa plateau f m,mesa plateau m,moor,mushroomislandshore,mystic grove,ominous woods,origin valley,outback,pasture,plains,prairie,redwood forest,roofed forest,roofed forest m,sacred springs,savanna,savanna m,savanna plateau,savanna plateau m,seasonal forest,shield,shrubland,snowy coniferous forest,spruce woods,stone beach,sunflower plains,taiga,taiga m,taigahills,temperate rainforest,thicket,timber,tropics,tundra,wasteland,woodland
weight=6

embed_into_distance=2
acceptable_target_blocks=stone,grass,dirt,sand,gravel,sandstone
dimensions=7,12,9
cut_in_buffer=1
max_leveling=2
leveling_buffer=1
preserve_water=0
preserve_lava=0
preserve_plants=0
max_cut_in=3
random_height_offset=-3,1

rule1=0,90,cobblestone,cobblestone,cobblestone,mossy_cobblestone,monster_egg-1
rule2=0,100,preserveBlock
rule3=0,100,cobblestone,cobblestone,cobblestone,mossy_cobblestone,dirt,monster_egg-1
rule4=0,20,planks,planks,planks,cobblestone,dirtß
rule5=0,90,log
rule6=0,10,glass_pane
rule7=0,75,planks
rule8=0,50,oak_stairs-1
rule9=0,50,oak_stairs-3
rule10=0,65,planks
rule11=0,50,oak_stairs
rule12=0,50,oak_stairs-2
rule13=0,100,MobSpawner:Zombie,MobSpawner:Skeleton,MobSpawner:Spider,MobSpawner:Spider,MobSpawner:MoCreatures.Werewolf,MobSpawner:MoCreatures.Bear
rule14=1,100,ChestGenHook:pyramidJungleChest:3,MediumChest,HardChest,ChestGenHook:dungeonChest:3

layer
2,2,1,1,1,1,1,1,1
2,2,1,3,3,3,3,3,1
2,2,1,3,3,3,3,3,1
2,2,1,3,3,3,3,3,1
2,2,1,3,3,3,3,3,1
1,1,1,3,3,13,3,3,1
1,3,3,3,3,3,3,3,1
1,3,3,3,3,3,3,3,1
1,3,3,3,3,3,3,3,1
1,3,3,3,3,3,3,3,1
1,1,1,1,1,1,1,1,1
2,2,2,2,2,2,2,2,2
endlayer

layer
0,0,1,1,1,1,1,1,1
0,0,1,4,4,4,4,4,1
0,0,1,4,4,4,4,4,1
0,0,1,4,4,4,4,4,1
0,0,1,4,4,4,4,4,1
1,1,1,4,4,14,4,4,1
1,4,4,4,4,4,4,4,1
1,4,4,4,4,4,4,4,1
1,4,4,4,4,4,4,4,1
1,4,4,4,4,4,4,4,1
1,1,0,1,1,1,1,1,1
0,0,0,0,0,0,0,0,0
endlayer

layer
0,0,1,1,1,1,1,1,1
0,0,5,0,0,0,0,0,5
0,0,6,0,0,0,0,0,6
0,0,6,0,0,0,0,0,6
0,0,5,0,0,0,0,0,5
1,7,7,0,0,0,0,0,7
5,0,0,0,0,0,0,0,5
6,0,0,0,0,0,0,0,6
6,0,0,0,0,0,0,0,6
5,0,0,0,0,0,0,0,5
1,7,0,7,5,6,5,7,1
0,0,0,0,0,0,0,0,0
endlayer

layer
0,9,1,1,1,1,1,1,1
0,9,1,0,0,0,0,0,1
0,9,1,0,0,0,0,0,1
0,9,1,0,0,0,0,0,1
11,10,1,0,0,0,0,0,1
1,7,7,0,0,0,0,0,1
1,0,0,0,0,0,0,0,1
1,0,0,0,0,0,0,0,1
1,0,0,0,0,0,0,0,1
1,0,0,0,0,0,0,0,1
1,7,7,7,7,7,7,7,1
8,8,8,8,8,8,8,8,8
endlayer

layer
0,0,9,10,5,6,5,10,12
0,0,9,10,0,0,0,10,12
0,0,9,10,0,0,0,10,12
0,0,9,10,0,0,0,10,12
0,0,9,10,0,0,0,10,12
11,11,10,10,0,0,0,10,12
10,10,10,10,0,0,0,10,10
10,0,0,0,0,0,0,10,10
10,0,0,0,0,0,0,10,10
10,10,10,10,10,10,10,10,10
8,8,8,8,8,8,8,8,8
0,0,0,0,0,0,0,0,0
endlayer

layer
0,0,0,9,10,10,10,12,0
0,0,0,9,10,0,10,12,0
0,0,0,9,10,0,10,12,0
0,0,0,9,10,0,10,12,0
0,0,0,9,10,0,10,12,0
0,0,0,9,10,0,10,12,0
11,11,11,10,10,0,10,10,11
10,10,10,10,10,10,10,10,10
10,10,10,10,10,10,10,10,10
8,8,8,8,8,8,8,8,8
0,0,0,0,0,0,0,0,0
0,0,0,0,0,0,0,0,0
endlayer

layer
0,0,0,0,9,10,12,0,0
0,0,0,0,9,10,12,0,0
0,0,0,0,9,10,12,0,0
0,0,0,0,9,10,12,0,0
0,0,0,0,9,10,12,0,0
0,0,0,0,9,10,12,0,0
0,0,0,0,9,10,12,0,0
11,11,11,11,10,10,10,11,11
8,8,8,8,8,8,8,8,8
0,0,0,0,0,0,0,0,0
0,0,0,0,0,0,0,0,0
0,0,0,0,0,0,0,0,0
endlayer

