biomesToSpawnIn=birch forest,birch forest hills,birch forest hills m,birch forest m,boreal forest,brushland,chaparral,cherry blossom grove,cold taiga,cold taiga hills,cold taiga m,coniferous forest,dead forest,deciduous forest,desert,desert m,deserthills,dunes,extreme hills edge,fen,flower field,flower forest,forest,foresthills,grassland,grove,heathland,highland,lavender fields,lush desert,lush swamp,maple woods,marsh,meadow,mega spruce taiga,mega taiga,mega taiga hills,mesa plateau f,mesa plateau f m,mesa plateau m,moor,mushroomislandshore,mystic grove,ominous woods,origin valley,outback,pasture,plains,prairie,redwood forest,roofed forest,roofed forest m,sacred springs,savanna,savanna m,savanna plateau,savanna plateau m,seasonal forest,shield,shrubland,snowy coniferous forest,spruce woods,stone beach,sunflower plains,taiga,taiga m,taigahills,temperate rainforest,thicket,timber,tropics,tundra,wasteland,woodland
weight=8

embed_into_distance=1
acceptable_target_blocks=stone,grass,dirt,sand,gravel
dimensions=8,10,12
allowable_overhang=0
max_cut_in=2
cut_in_buffer=1
max_leveling=2
leveling_buffer=1
preserve_water=1
preserve_lava=0
preserve_plants=1
random_height_offset=-3,0

rule1=0,100,double_stone_slab
rule2=0,100,planks
rule3=0,100,cobblestone
rule4=0,100,grass
rule5=0,100,stone_stairs
rule6=0,100,stone_stairs-1
rule7=0,100,stone_stairs-2
rule8=0,100,stone_stairs-3
rule0=0,100,preserveBlock
rule9=0,100,MobSpawner:Skeleton,MobSpawner:Spider,MobSpawner:Zombie
rule10=1,100,ChestGenHook:pyramidJungleChest:2,MediumChest,HardChest,ChestGenHook:dungeonChest:2

layer
1,3,3,3,3,3,3,3,3,3,3,1
3,0,0,0,2,2,2,2,2,2,2,2
3,0,0,0,0,0,2,2,2,2,2,3
3,0,0,2,0,0,2,2,0,2,2,3
3,0,2,2,2,2,2,2,2,2,2,3
3,2,2,2,2,2,9,3,3,3,3,1
3,2,2,0,2,2,3,4,4,4,4,4
3,2,2,0,2,2,3,4,4,4,4,4
3,2,0,0,2,0,3,4,4,4,4,4
1,3,3,3,3,3,1,4,4,4,4,4
endlayer

layer
1,3,3,3,3,3,3,3,3,0,3,1
3,9,9,0,0,0,0,0,0,0,0,0
3,9,0,0,0,0,0,0,0,0,0,3
9,9,9,0,0,0,0,0,0,0,0,3
3,9,0,0,0,0,10,0,0,0,0,0
3,3,0,3,3,3,3,3,3,3,3,1
3,0,0,0,0,0,3,0,0,0,0,0
3,0,0,0,0,0,3,0,0,0,0,9
3,0,0,0,0,0,3,0,0,0,9,9
1,3,3,3,3,3,1,0,0,9,9,9
endlayer

layer
1,3,0,0,0,3,3,3,0,0,3,1
3,9,0,0,0,0,0,0,0,0,0,0
9,9,0,0,0,0,0,0,0,0,0,3
9,0,0,0,0,0,0,0,0,0,0,0
3,0,0,0,0,0,0,0,0,0,0,0
3,3,0,3,3,3,0,3,0,0,0,0
3,0,0,0,0,0,0,0,0,0,0,0
0,0,0,0,0,0,0,0,0,0,0,0
3,0,0,0,0,0,3,0,0,0,0,9
1,3,0,0,0,3,1,0,0,0,0,9
endlayer

layer
0,3,0,0,0,0,0,0,0,0,3,1
3,0,0,0,0,0,0,0,0,0,0,0
0,0,0,0,0,0,0,0,0,0,0,3
0,0,0,0,0,0,0,0,0,0,0,0
3,0,0,0,0,0,0,0,0,0,0,0
3,3,0,0,0,3,3,3,0,0,0,0
3,0,0,0,0,0,3,0,0,0,0,0
0,0,0,0,0,0,0,0,0,0,0,0
0,0,0,0,0,0,0,0,0,0,0,0
1,3,0,0,0,3,1,0,0,0,0,0
endlayer

layer
0,3,3,3,3,0,0,0,3,3,3,0
0,0,0,0,0,0,0,0,0,0,0,0
0,0,0,0,0,0,0,0,0,0,0,3
0,0,0,0,0,0,0,0,0,0,0,0
3,0,0,0,0,0,0,0,0,0,0,0
3,3,0,0,0,3,3,3,3,3,0,0
0,0,0,0,0,0,3,0,0,0,0,0
0,0,0,0,0,0,3,0,0,0,0,0
0,0,0,0,0,0,0,0,0,0,0,0
0,3,0,0,0,3,1,0,0,0,0,0
endlayer

layer
0,5,5,5,5,0,0,0,5,5,0,0
0,3,0,0,0,0,0,0,3,0,0,0
3,0,0,0,0,0,0,0,0,0,0,3
0,0,0,0,0,0,0,0,0,0,0,3
3,0,0,0,0,0,0,3,3,3,3,0
3,3,0,0,0,0,0,6,6,6,0,0
0,0,0,0,0,0,7,0,0,0,0,0
0,0,0,0,0,0,7,0,0,0,0,0
0,0,0,0,0,0,0,0,0,0,0,0
0,3,3,0,3,3,7,0,0,0,0,0
endlayer

layer
0,0,0,0,0,0,0,0,0,0,0,0
0,5,0,5,5,5,5,5,0,0,0,0
3,3,3,3,3,3,0,3,0,0,0,0
3,0,0,3,3,0,3,3,0,0,0,3
6,3,3,3,0,0,0,6,0,0,0,6
0,8,3,3,3,0,0,0,0,0,0,0
0,8,0,0,0,0,0,0,0,0,0,0
0,8,0,0,0,0,0,0,0,0,0,0
0,0,0,0,0,0,0,0,0,0,0,0
0,8,3,3,3,7,0,0,0,0,0,0
endlayer

layer
0,0,0,0,0,0,0,0,0,0,0,0
0,0,0,0,0,0,0,0,0,0,0,0
5,5,0,5,5,5,5,5,0,0,0,0
6,0,0,0,3,6,6,6,0,0,0,6
0,0,8,3,7,0,0,0,0,0,0,0
0,0,8,3,0,0,0,0,0,0,0,0
0,0,8,3,7,0,0,0,0,0,0,0
0,0,0,0,0,0,0,0,0,0,0,0
0,0,8,0,7,0,0,0,0,0,0,0
0,0,8,3,7,0,0,0,0,0,0,0
endlayer

