biomesToSpawnIn=bamboo forest,bayou,birch forest,birch forest hills,birch forest hills m,birch forest m,bog,boreal forest,brushland,chaparral,cherry blossom grove,cold taiga,cold taiga hills,cold taiga m,coniferous forest,dead forest,dead swamp,deciduous forest,extreme hills,extreme hills edge,extreme hills m,extreme hills+,extreme hills+ m,fen,flower field,flower forest,forest,foresthills,frozenriver,grassland,grove,heathland,highland,ice mountains,ice plains,jade cliffs,jungle,jungle m,jungleedge,jungleedge m,junglehills,lavender fields,lush desert,lush swamp,maple woods,marsh,meadow,mega spruce taiga,mega taiga,mega taiga hills,mesa plateau f,mesa plateau f m,mesa plateau m,moor,mushroomislandshore,mystic grove,ominous woods,origin valley,outback,pasture,plains,prairie,quagmire,rainforest,redwood forest,river,roofed forest,roofed forest m,sacred springs,savanna,savanna m,savanna plateau,savanna plateau m,seasonal forest,shield,shrubland,silkglades,sludgepit,snowy coniferous forest,spruce woods,stone beach,sunflower plains,swampland,swampland m,taiga,taiga m,taigahills,temperate rainforest,thicket,timber,tropical rainforest,tropics,tundra,wasteland,wetland,woodland
weight=10
embed_into_distance=5
acceptable_target_blocks=grass,dirt
dimensions=7,42,19
allowable_overhang=10
max_leveling=0
cut_in_buffer=0
leveling_buffer=0
preserve_water=0
preserve_lava=0
preserve_plants=1
max_cut_in=1
random_height_offset=-1,5

rule1=0,100,grass
rule2=0,100,dirt
rule3=0,100,MediumMobSpawn,MediumMobSpawn,MediumMobSpawn,dirt
rule4=0,100,MediumChest,MediumChest,dirt,dirt
rule5=0,100,cobblestone,cobblestone,cobblestone,cobblestone,cobblestone,cobblestone,cobblestone,cobblestone,cobblestone,cobblestone,cobblestone,cobblestone,cobblestone,cobblestone,cobblestone,cobblestone,cobblestone,cobblestone,cobblestone,mossy_cobblestone
rule6=0,100,stone_slab
rule7=0,100,log-1
rule8=0,100,preserveBlock

layer
1,1,1,1,1,1,1,1,1,1,1,1,1,1,1,1,1,1,1
1,1,1,2,2,2,2,2,2,2,2,2,2,2,2,2,1,1,1
1,1,2,2,2,2,2,2,2,2,2,2,2,2,2,2,2,1,1
1,2,2,2,2,2,2,2,2,2,2,2,2,2,2,2,2,2,1
1,2,2,2,2,2,2,2,2,2,2,2,2,2,2,2,2,2,1
1,2,2,2,2,2,2,2,2,2,2,2,2,2,2,2,2,2,1
1,2,2,2,2,2,2,2,2,2,2,2,2,2,2,2,2,2,1
1,2,2,2,2,2,2,2,2,2,2,2,2,2,2,2,2,2,1
1,2,2,2,2,2,2,2,2,2,2,2,2,2,2,2,2,2,1
1,2,2,2,2,2,2,2,2,2,2,2,2,2,2,2,2,2,1
1,2,2,2,2,2,2,2,2,2,2,2,2,2,2,2,2,2,1
1,2,2,2,2,2,2,2,2,2,2,2,2,2,2,2,2,2,1
1,2,2,2,2,2,2,2,2,2,2,2,2,2,2,2,2,2,1
1,2,2,2,2,2,2,2,2,2,2,2,2,2,2,2,2,2,1
1,2,2,2,2,2,2,2,2,2,2,2,2,2,2,2,2,2,1
1,2,2,2,2,2,2,2,2,2,2,2,2,2,2,2,2,2,1
1,2,2,2,2,2,2,2,2,2,2,2,2,2,2,2,2,2,1
1,2,2,2,2,2,2,2,2,2,2,2,2,2,2,2,2,2,1
1,2,2,2,2,3,2,2,2,2,2,2,2,4,2,2,2,2,1
1,2,2,2,2,4,2,2,2,2,2,2,2,3,2,2,2,2,1
1,2,2,2,2,2,2,2,2,2,2,2,2,2,2,2,2,2,1
1,2,2,2,2,2,2,2,2,2,2,2,2,2,2,2,2,2,1
1,2,2,2,2,2,2,2,2,2,2,2,2,2,2,2,2,2,1
1,2,2,2,2,2,2,2,2,2,2,2,2,2,2,2,2,2,1
1,2,2,2,2,2,2,2,2,2,2,2,2,2,2,2,2,2,1
1,2,2,2,2,4,2,2,2,2,2,2,2,3,2,2,2,2,1
1,2,2,2,2,3,2,2,2,2,2,2,2,4,2,2,2,2,1
1,2,2,2,2,2,2,2,2,2,2,2,2,2,2,2,2,2,1
1,2,2,2,2,2,2,2,2,2,2,2,2,2,2,2,2,2,1
1,2,2,2,2,2,2,2,2,2,2,2,2,2,2,2,2,2,1
1,2,2,2,2,2,2,2,2,2,2,2,2,2,2,2,2,2,1
1,2,2,2,2,2,2,2,2,2,2,2,2,2,2,2,2,2,1
1,2,2,2,2,2,2,2,2,2,2,2,2,2,2,2,2,2,1
1,2,2,2,2,2,2,2,2,2,2,2,2,2,2,2,2,2,1
1,2,2,2,2,2,2,2,2,2,2,2,2,2,2,2,2,2,1
1,2,2,2,2,2,2,2,2,2,2,2,2,2,2,2,2,2,1
1,2,2,2,2,2,2,2,2,2,2,2,2,2,2,2,2,2,1
1,2,2,2,2,2,2,2,2,2,2,2,2,2,2,2,2,2,1
1,2,2,2,2,2,2,2,2,2,2,2,2,2,2,2,2,2,1
1,1,2,2,2,2,2,2,2,2,2,2,2,2,2,2,2,1,1
1,1,1,2,2,2,2,2,2,2,2,2,2,2,2,2,1,1,1
1,1,1,1,1,1,1,1,1,1,1,1,1,1,1,1,1,1,1
endlayer

layer
8,8,8,8,8,8,8,8,8,8,8,8,8,8,8,8,8,8,8
8,8,8,1,1,1,1,1,1,1,1,1,1,1,1,1,8,8,8
8,8,1,2,2,2,2,2,2,2,2,2,2,2,2,2,1,8,8
8,1,1,2,2,2,2,2,2,2,2,2,2,2,2,2,1,1,8
8,1,2,2,2,2,2,2,2,2,2,2,2,2,2,2,2,1,8
8,1,2,2,2,2,2,2,2,2,2,2,2,2,2,2,2,1,8
8,1,2,2,2,2,2,2,2,2,2,2,2,2,2,2,2,1,8
8,1,2,2,2,2,2,2,2,2,2,2,2,2,2,2,2,1,8
8,1,2,2,2,2,5,5,5,5,5,5,5,2,2,2,2,1,8
8,1,2,2,2,5,7,0,0,7,0,0,7,5,2,2,2,1,8
8,1,2,2,2,5,0,0,0,0,0,0,0,5,2,2,2,1,8
8,1,2,2,2,5,0,0,0,0,0,0,0,5,2,2,2,1,8
8,1,2,2,2,5,0,0,0,0,0,0,0,5,2,2,2,1,8
8,1,2,2,2,2,5,7,0,0,0,7,5,2,2,2,2,1,8
8,1,2,2,2,2,5,0,0,0,0,0,5,2,2,2,2,1,8
8,1,2,2,2,2,5,0,0,0,0,0,5,2,2,2,2,1,8
8,1,2,2,2,5,5,0,0,0,0,0,5,5,2,2,2,1,8
8,1,2,2,5,0,0,7,0,0,0,7,0,0,5,2,2,1,8
8,1,2,5,5,6,0,0,0,0,0,0,0,6,5,5,2,1,8
8,1,2,5,5,6,0,0,0,0,0,0,0,6,5,5,2,1,8
8,1,2,2,5,0,0,7,0,0,0,7,0,0,5,2,2,1,8
8,1,2,2,2,5,5,0,0,0,0,0,5,5,2,2,2,1,8
8,1,2,2,2,2,5,0,0,0,0,0,5,2,2,2,2,1,8
8,1,2,2,2,5,5,0,0,0,0,0,5,5,2,2,2,1,8
8,1,2,2,5,0,0,7,0,0,0,7,0,0,5,2,2,1,8
8,1,2,5,5,6,0,0,0,0,0,0,0,6,5,5,2,1,8
8,1,2,5,5,6,0,0,0,0,0,0,0,6,5,5,2,1,8
8,1,2,2,5,0,0,7,0,0,0,7,0,0,5,2,2,1,8
8,1,2,2,2,5,5,0,0,0,0,0,5,5,2,2,2,1,8
8,1,2,2,2,2,5,0,0,0,0,0,5,2,2,2,2,1,8
8,1,2,2,2,2,5,0,0,0,0,0,5,2,2,2,2,1,8
8,1,2,2,2,2,5,7,0,0,0,7,5,2,2,2,2,1,8
8,1,2,2,2,5,0,0,0,0,0,0,0,5,2,2,2,1,8
8,1,2,2,2,5,0,0,0,0,0,0,0,5,2,2,2,1,8
8,1,2,2,2,5,0,0,0,0,0,0,0,5,2,2,2,1,8
8,1,2,2,2,5,7,0,0,7,0,0,7,5,2,2,2,1,8
8,1,2,2,2,2,5,5,5,5,5,5,5,2,2,2,2,1,8
8,1,2,2,2,2,2,2,2,2,2,2,2,2,2,2,2,1,8
8,1,1,2,2,2,2,2,2,2,2,2,2,2,2,2,1,1,8
8,8,1,2,2,2,2,2,2,2,2,2,2,2,2,2,1,8,8
8,8,8,1,1,1,1,1,1,1,1,1,1,1,1,1,8,8,8
8,8,8,8,8,8,8,8,8,8,8,8,8,8,8,8,8,8,8
endlayer

layer
8,8,8,8,8,8,8,8,8,8,8,8,8,8,8,8,8,8,8
8,8,8,8,8,8,8,8,8,8,8,8,8,8,8,8,8,8,8
8,8,8,1,1,1,1,1,1,1,1,1,1,1,1,1,8,8,8
8,8,8,1,1,1,1,1,1,1,1,1,1,1,1,1,8,8,8
8,8,1,1,2,2,2,2,2,2,2,2,2,2,2,1,1,8,8
8,8,1,2,2,2,2,2,2,2,2,2,2,2,2,2,1,8,8
8,8,1,2,2,2,2,2,2,2,2,2,2,2,2,2,1,8,8
8,8,1,2,2,2,2,2,2,2,2,2,2,2,2,2,1,8,8
8,8,1,2,2,2,5,5,5,5,5,5,5,2,2,2,1,8,8
8,8,1,2,2,5,7,0,0,7,0,0,7,5,2,2,1,8,8
8,8,1,2,2,5,0,0,0,0,0,0,0,5,2,2,1,8,8
8,8,1,2,2,5,0,0,0,0,0,0,0,5,2,2,1,8,8
8,8,1,2,2,5,0,0,0,0,0,0,0,5,2,2,1,8,8
8,8,1,2,2,2,5,7,0,0,0,7,5,2,2,2,1,8,8
8,8,1,2,2,2,5,0,0,0,0,0,5,2,2,2,1,8,8
8,8,1,2,2,2,5,0,0,0,0,0,5,2,2,2,1,8,8
8,8,1,2,2,5,5,0,0,0,0,0,5,5,2,2,1,8,8
8,8,1,2,5,0,0,7,0,0,0,7,0,0,5,2,1,8,8
8,8,1,5,0,0,0,0,0,0,0,0,0,0,0,5,1,8,8
8,8,1,5,0,0,0,0,0,0,0,0,0,0,0,5,1,8,8
8,8,1,2,5,0,0,7,0,0,0,7,0,0,5,2,1,8,8
8,8,1,2,2,5,5,0,0,0,0,0,5,5,2,2,1,8,8
8,8,1,2,2,2,5,0,0,0,0,0,5,2,2,2,1,8,8
8,8,1,2,2,5,5,0,0,0,0,0,5,5,2,2,1,8,8
8,8,1,2,5,0,0,7,0,0,0,7,0,0,5,2,1,8,8
8,8,1,5,0,0,0,0,0,0,0,0,0,0,0,5,1,8,8
8,8,1,5,0,0,0,0,0,0,0,0,0,0,0,5,1,8,8
8,8,1,2,5,0,0,7,0,0,0,7,0,0,5,2,1,8,8
8,8,1,2,2,5,5,0,0,0,0,0,5,5,2,2,1,8,8
8,8,1,2,2,2,5,0,0,0,0,0,5,2,2,2,1,8,8
8,8,1,2,2,2,5,0,0,0,0,0,5,2,2,2,1,8,8
8,8,1,2,2,2,5,7,0,0,0,7,5,2,2,2,1,8,8
8,8,1,2,2,5,0,0,0,0,0,0,0,5,2,2,1,8,8
8,8,1,2,2,5,0,0,0,0,0,0,0,5,2,2,1,8,8
8,8,1,2,2,5,0,0,0,0,0,0,0,5,2,2,1,8,8
8,8,1,2,2,5,7,0,0,7,0,0,7,5,2,2,1,8,8
8,8,1,2,2,2,5,5,5,5,5,5,5,2,2,2,1,8,8
8,8,1,1,2,2,2,2,2,2,2,2,2,2,2,1,1,8,8
8,8,8,1,1,1,1,1,1,1,1,1,1,1,1,1,8,8,8
8,8,8,1,1,1,1,1,1,1,1,1,1,1,1,1,8,8,8
8,8,8,8,8,8,8,8,8,8,8,8,8,8,8,8,8,8,8
8,8,8,8,8,8,8,8,8,8,8,8,8,8,8,8,8,8,8
endlayer

layer
8,8,8,8,8,8,8,8,8,8,8,8,8,8,8,8,8,8,8
8,8,8,8,8,8,8,8,8,8,8,8,8,8,8,8,8,8,8
8,8,8,8,8,8,8,8,8,8,8,8,8,8,8,8,8,8,8
8,8,8,8,8,8,8,8,8,8,8,8,8,8,8,8,8,8,8
8,8,8,8,1,1,1,1,1,1,1,1,1,1,1,8,8,8,8
8,8,8,1,1,2,2,2,2,2,2,2,2,2,1,1,8,8,8
8,8,8,1,2,2,2,2,2,2,2,2,2,2,2,1,8,8,8
8,8,8,1,2,2,2,2,2,2,2,2,2,2,2,1,8,8,8
8,8,8,1,2,2,2,2,2,2,2,2,2,2,2,1,8,8,8
8,8,8,1,2,2,5,5,5,5,5,5,5,2,2,1,8,8,8
8,8,8,1,2,2,5,5,5,5,5,5,5,2,2,1,8,8,8
8,8,8,1,2,2,5,5,5,5,5,5,5,2,2,1,8,8,8
8,8,8,1,2,2,5,5,5,5,5,5,5,2,2,1,8,8,8
8,8,8,1,2,2,2,5,5,5,5,5,2,2,2,1,8,8,8
8,8,8,1,2,2,2,5,5,5,5,5,2,2,2,1,8,8,8
8,8,8,1,2,2,2,5,5,5,5,5,2,2,2,1,8,8,8
8,8,8,1,2,2,2,5,5,5,5,5,2,2,2,1,8,8,8
8,8,8,1,2,5,5,5,5,5,5,5,5,5,2,1,8,8,8
8,8,8,1,5,5,5,5,5,5,5,5,5,5,5,1,8,8,8
8,8,8,1,5,5,5,5,5,5,5,5,5,5,5,1,8,8,8
8,8,8,1,2,5,5,5,5,5,5,5,5,5,2,1,8,8,8
8,8,8,1,2,2,2,5,5,5,5,5,2,2,2,1,8,8,8
8,8,8,1,2,2,2,5,5,5,5,5,2,2,2,1,8,8,8
8,8,8,1,2,2,2,5,5,5,5,5,2,2,2,1,8,8,8
8,8,8,1,2,5,5,5,5,5,5,5,5,5,2,1,8,8,8
8,8,8,1,5,5,5,5,5,5,5,5,5,5,5,1,8,8,8
8,8,8,1,5,5,5,5,5,5,5,5,5,5,5,1,8,8,8
8,8,8,1,2,5,5,5,5,5,5,5,5,5,2,1,8,8,8
8,8,8,1,2,2,2,5,5,5,5,5,2,2,2,1,8,8,8
8,8,8,1,2,2,2,5,5,5,5,5,2,2,2,1,8,8,8
8,8,8,1,2,2,2,5,5,5,5,5,2,2,2,1,8,8,8
8,8,8,1,2,2,2,5,5,5,5,5,2,2,2,1,8,8,8
8,8,8,1,2,2,5,5,5,5,5,5,5,2,2,1,8,8,8
8,8,8,1,2,2,5,5,5,5,5,5,5,2,2,1,8,8,8
8,8,8,1,2,2,5,5,5,5,5,5,5,2,2,1,8,8,8
8,8,8,1,2,2,5,5,5,5,5,5,5,2,2,1,8,8,8
8,8,8,1,1,2,2,2,2,2,2,2,2,2,1,1,8,8,8
8,8,8,8,1,1,1,1,1,1,1,1,1,1,1,8,8,8,8
8,8,8,8,8,8,8,8,8,8,8,8,8,8,8,8,8,8,8
8,8,8,8,8,8,8,8,8,8,8,8,8,8,8,8,8,8,8
8,8,8,8,8,8,8,8,8,8,8,8,8,8,8,8,8,8,8
8,8,8,8,8,8,8,8,8,8,8,8,8,8,8,8,8,8,8
endlayer

layer
8,8,8,8,8,8,8,8,8,8,8,8,8,8,8,8,8,8,8
8,8,8,8,8,8,8,8,8,8,8,8,8,8,8,8,8,8,8
8,8,8,8,8,8,8,8,8,8,8,8,8,8,8,8,8,8,8
8,8,8,8,8,8,8,8,8,8,8,8,8,8,8,8,8,8,8
8,8,8,8,8,8,8,8,8,8,8,8,8,8,8,8,8,8,8
8,8,8,8,8,1,1,1,1,1,1,1,1,1,8,8,8,8,8
8,8,8,8,1,1,1,1,1,1,1,1,1,1,1,8,8,8,8
8,8,8,8,1,2,2,2,2,2,2,2,2,2,1,8,8,8,8
8,8,8,8,1,2,2,2,2,2,2,2,2,2,1,8,8,8,8
8,8,8,8,1,2,2,2,2,2,2,2,2,2,1,8,8,8,8
8,8,8,8,1,2,2,2,2,2,2,2,2,2,1,8,8,8,8
8,8,8,8,1,2,2,2,2,2,2,2,2,2,1,8,8,8,8
8,8,8,8,1,2,2,2,2,2,2,2,2,2,1,8,8,8,8
8,8,8,8,1,2,2,2,2,2,2,2,2,2,1,8,8,8,8
8,8,8,8,1,2,2,2,2,2,2,2,2,2,1,8,8,8,8
8,8,8,8,1,2,2,2,2,2,2,2,2,2,1,8,8,8,8
8,8,8,8,1,2,2,2,2,2,2,2,2,2,1,8,8,8,8
8,8,8,8,1,2,2,2,2,2,2,2,2,2,1,8,8,8,8
8,8,8,8,1,2,2,2,2,2,2,2,2,2,1,8,8,8,8
8,8,8,8,1,2,2,2,2,2,2,2,2,2,1,8,8,8,8
8,8,8,8,1,2,2,2,2,2,2,2,2,2,1,8,8,8,8
8,8,8,8,1,2,2,2,2,2,2,2,2,2,1,8,8,8,8
8,8,8,8,1,2,2,2,2,2,2,2,2,2,1,8,8,8,8
8,8,8,8,1,2,2,2,2,2,2,2,2,2,1,8,8,8,8
8,8,8,8,1,2,2,2,2,2,2,2,2,2,1,8,8,8,8
8,8,8,8,1,2,2,2,2,2,2,2,2,2,1,8,8,8,8
8,8,8,8,1,2,2,2,2,2,2,2,2,2,1,8,8,8,8
8,8,8,8,1,2,2,2,2,2,2,2,2,2,1,8,8,8,8
8,8,8,8,1,2,2,2,2,2,2,2,2,2,1,8,8,8,8
8,8,8,8,1,2,2,2,2,2,2,2,2,2,1,8,8,8,8
8,8,8,8,1,2,2,2,2,2,2,2,2,2,1,8,8,8,8
8,8,8,8,1,2,2,2,2,2,2,2,2,2,1,8,8,8,8
8,8,8,8,1,2,2,2,2,2,2,2,2,2,1,8,8,8,8
8,8,8,8,1,2,2,2,2,2,2,2,2,2,1,8,8,8,8
8,8,8,8,1,2,2,2,2,2,2,2,2,2,1,8,8,8,8
8,8,8,8,1,1,1,1,1,1,1,1,1,1,1,8,8,8,8
8,8,8,8,8,1,1,1,1,1,1,1,1,1,8,8,8,8,8
8,8,8,8,8,8,8,8,8,8,8,8,8,8,8,8,8,8,8
8,8,8,8,8,8,8,8,8,8,8,8,8,8,8,8,8,8,8
8,8,8,8,8,8,8,8,8,8,8,8,8,8,8,8,8,8,8
8,8,8,8,8,8,8,8,8,8,8,8,8,8,8,8,8,8,8
8,8,8,8,8,8,8,8,8,8,8,8,8,8,8,8,8,8,8
endlayer

layer
8,8,8,8,8,8,8,8,8,8,8,8,8,8,8,8,8,8,8
8,8,8,8,8,8,8,8,8,8,8,8,8,8,8,8,8,8,8
8,8,8,8,8,8,8,8,8,8,8,8,8,8,8,8,8,8,8
8,8,8,8,8,8,8,8,8,8,8,8,8,8,8,8,8,8,8
8,8,8,8,8,8,8,8,8,8,8,8,8,8,8,8,8,8,8
8,8,8,8,8,8,8,8,8,8,8,8,8,8,8,8,8,8,8
8,8,8,8,8,8,8,8,8,8,8,8,8,8,8,8,8,8,8
8,8,8,8,8,1,1,1,1,1,1,1,1,1,8,8,8,8,8
8,8,8,8,8,1,2,2,2,2,2,2,2,1,8,8,8,8,8
8,8,8,8,8,1,2,2,2,2,2,2,2,1,8,8,8,8,8
8,8,8,8,8,1,2,2,2,2,2,2,2,1,8,8,8,8,8
8,8,8,8,8,1,2,2,2,2,2,2,2,1,8,8,8,8,8
8,8,8,8,8,1,2,2,2,2,2,2,2,1,8,8,8,8,8
8,8,8,8,8,1,2,2,2,2,2,2,2,1,8,8,8,8,8
8,8,8,8,8,1,2,2,2,2,2,2,2,1,8,8,8,8,8
8,8,8,8,8,1,2,2,2,2,2,2,2,1,8,8,8,8,8
8,8,8,8,8,1,2,2,2,2,2,2,2,1,8,8,8,8,8
8,8,8,8,8,1,2,2,2,2,2,2,2,1,8,8,8,8,8
8,8,8,8,8,1,2,2,2,2,2,2,2,1,8,8,8,8,8
8,8,8,8,8,1,2,2,2,2,2,2,2,1,8,8,8,8,8
8,8,8,8,8,1,2,2,2,2,2,2,2,1,8,8,8,8,8
8,8,8,8,8,1,2,2,2,2,2,2,2,1,8,8,8,8,8
8,8,8,8,8,1,2,2,2,2,2,2,2,1,8,8,8,8,8
8,8,8,8,8,1,2,2,2,2,2,2,2,1,8,8,8,8,8
8,8,8,8,8,1,2,2,2,2,2,2,2,1,8,8,8,8,8
8,8,8,8,8,1,2,2,2,2,2,2,2,1,8,8,8,8,8
8,8,8,8,8,1,2,2,2,2,2,2,2,1,8,8,8,8,8
8,8,8,8,8,1,2,2,2,2,2,2,2,1,8,8,8,8,8
8,8,8,8,8,1,2,2,2,2,2,2,2,1,8,8,8,8,8
8,8,8,8,8,1,2,2,2,2,2,2,2,1,8,8,8,8,8
8,8,8,8,8,1,2,2,2,2,2,2,2,1,8,8,8,8,8
8,8,8,8,8,1,2,2,2,2,2,2,2,1,8,8,8,8,8
8,8,8,8,8,1,2,2,2,2,2,2,2,1,8,8,8,8,8
8,8,8,8,8,1,2,2,2,2,2,2,2,1,8,8,8,8,8
8,8,8,8,8,1,1,1,1,1,1,1,1,1,8,8,8,8,8
8,8,8,8,8,8,8,8,8,8,8,8,8,8,8,8,8,8,8
8,8,8,8,8,8,8,8,8,8,8,8,8,8,8,8,8,8,8
8,8,8,8,8,8,8,8,8,8,8,8,8,8,8,8,8,8,8
8,8,8,8,8,8,8,8,8,8,8,8,8,8,8,8,8,8,8
8,8,8,8,8,8,8,8,8,8,8,8,8,8,8,8,8,8,8
8,8,8,8,8,8,8,8,8,8,8,8,8,8,8,8,8,8,8
8,8,8,8,8,8,8,8,8,8,8,8,8,8,8,8,8,8,8
endlayer

layer
8,8,8,8,8,8,8,8,8,8,8,8,8,8,8,8,8,8,8
8,8,8,8,8,8,8,8,8,8,8,8,8,8,8,8,8,8,8
8,8,8,8,8,8,8,8,8,8,8,8,8,8,8,8,8,8,8
8,8,8,8,8,8,8,8,8,8,8,8,8,8,8,8,8,8,8
8,8,8,8,8,8,8,8,8,8,8,8,8,8,8,8,8,8,8
8,8,8,8,8,8,8,8,8,8,8,8,8,8,8,8,8,8,8
8,8,8,8,8,8,8,8,8,8,8,8,8,8,8,8,8,8,8
8,8,8,8,8,8,8,8,8,8,8,8,8,8,8,8,8,8,8
8,8,8,8,8,8,1,1,1,1,1,1,1,8,8,8,8,8,8
8,8,8,8,8,8,1,1,1,1,1,1,1,8,8,8,8,8,8
8,8,8,8,8,8,1,1,1,1,1,1,1,8,8,8,8,8,8
8,8,8,8,8,8,1,1,1,1,1,1,1,8,8,8,8,8,8
8,8,8,8,8,8,1,1,1,1,1,1,1,8,8,8,8,8,8
8,8,8,8,8,8,1,1,1,1,1,1,1,8,8,8,8,8,8
8,8,8,8,8,8,1,1,1,1,1,1,1,8,8,8,8,8,8
8,8,8,8,8,8,1,1,1,1,1,1,1,8,8,8,8,8,8
8,8,8,8,8,8,1,1,1,1,1,1,1,8,8,8,8,8,8
8,8,8,8,8,8,1,1,1,1,1,1,1,8,8,8,8,8,8
8,8,8,8,8,8,1,1,1,1,1,1,1,8,8,8,8,8,8
8,8,8,8,8,8,1,1,1,1,1,1,1,8,8,8,8,8,8
8,8,8,8,8,8,1,1,1,1,1,1,1,8,8,8,8,8,8
8,8,8,8,8,8,1,1,1,1,1,1,1,8,8,8,8,8,8
8,8,8,8,8,8,1,1,1,1,1,1,1,8,8,8,8,8,8
8,8,8,8,8,8,1,1,1,1,1,1,1,8,8,8,8,8,8
8,8,8,8,8,8,1,1,1,1,1,1,1,8,8,8,8,8,8
8,8,8,8,8,8,1,1,1,1,1,1,1,8,8,8,8,8,8
8,8,8,8,8,8,1,1,1,1,1,1,1,8,8,8,8,8,8
8,8,8,8,8,8,1,1,1,1,1,1,1,8,8,8,8,8,8
8,8,8,8,8,8,1,1,1,1,1,1,1,8,8,8,8,8,8
8,8,8,8,8,8,1,1,1,1,1,1,1,8,8,8,8,8,8
8,8,8,8,8,8,1,1,1,1,1,1,1,8,8,8,8,8,8
8,8,8,8,8,8,1,1,1,1,1,1,1,8,8,8,8,8,8
8,8,8,8,8,8,1,1,1,1,1,1,1,8,8,8,8,8,8
8,8,8,8,8,8,1,1,1,1,1,1,1,8,8,8,8,8,8
8,8,8,8,8,8,8,8,8,8,8,8,8,8,8,8,8,8,8
8,8,8,8,8,8,8,8,8,8,8,8,8,8,8,8,8,8,8
8,8,8,8,8,8,8,8,8,8,8,8,8,8,8,8,8,8,8
8,8,8,8,8,8,8,8,8,8,8,8,8,8,8,8,8,8,8
8,8,8,8,8,8,8,8,8,8,8,8,8,8,8,8,8,8,8
8,8,8,8,8,8,8,8,8,8,8,8,8,8,8,8,8,8,8
8,8,8,8,8,8,8,8,8,8,8,8,8,8,8,8,8,8,8
8,8,8,8,8,8,8,8,8,8,8,8,8,8,8,8,8,8,8
endlayer

