biomesToSpawnIn=desert,deserthills,beach
weight=10
embed_into_distance=1
acceptable_target_blocks=stone,grass,dirt,sand,gravel
dimensions=5,10,14
allowable_overhang=0
max_cut_in=1
cut_in_buffer=1
max_leveling=2
leveling_buffer=1
preserve_water=0
preserve_lava=0
preserve_plants=0
random_height_offset=-1,0


rule1=0,100,sand
rule2=0,100,sandstone
rule3=0,100,dirt
rule4=0,100,grass
rule5=0,100,stone_slab-1
rule6=0,100,sandstone-1
rule7=0,100,double_stone_slab-1
rule8=0,100,preserveBlock


layer
1,1,1,1,1,1,1,1,1,1,8,1,1,1
1,1,1,1,1,1,1,1,1,1,8,1,1,1
1,1,1,1,1,1,1,1,1,2,8,1,1,1
1,1,1,1,1,1,1,1,1,2,8,1,1,1
1,1,1,1,1,1,1,1,1,2,8,1,1,1
1,1,1,1,1,1,1,1,1,2,8,1,1,1
2,1,1,1,1,1,1,1,1,2,8,1,1,1
3,1,1,1,1,1,2,2,2,2,8,1,1,1
1,4,4,4,4,3,1,2,2,2,8,1,1,1
1,1,1,1,1,1,3,2,2,2,8,1,1,1
endlayer

layer
8,8,8,8,8,8,8,5,8,8,8,8,8,8
8,8,8,8,8,8,8,8,8,8,8,8,8,8
8,8,8,8,8,8,8,8,8,5,8,8,8,8
8,8,8,8,8,8,8,8,8,5,8,8,8,8
8,8,8,8,8,8,8,8,8,5,8,8,8,8
6,8,8,8,8,8,8,8,8,5,8,8,8,8
8,8,8,8,8,8,8,8,8,5,8,8,8,8
6,8,8,8,8,8,8,8,8,5,8,8,8,8
8,5,5,5,5,5,8,8,2,8,8,8,8,8
8,8,8,8,8,8,6,8,6,8,8,8,8,8
endlayer

layer
8,8,8,8,8,8,8,8,8,8,8,8,8,8
8,8,8,8,8,8,8,8,8,8,8,8,8,8
8,8,8,8,8,8,8,8,8,8,8,8,8,8
8,8,8,8,8,8,8,8,8,8,8,8,8,8
8,8,8,8,8,8,8,8,8,8,8,8,8,8
6,8,8,8,8,8,8,8,8,8,8,8,8,8
8,8,8,8,8,8,8,8,8,8,8,8,8,8
6,8,8,8,8,8,8,8,8,8,8,8,8,8
8,8,8,8,8,8,8,8,2,8,8,8,8,8
8,8,8,8,8,8,6,8,6,8,8,8,8,8
endlayer

layer
8,8,8,8,8,8,8,8,8,8,8,8,8,8
8,8,8,8,8,8,8,8,8,8,8,8,8,8
8,7,8,8,8,8,8,8,8,8,8,8,8,8
8,7,8,8,8,8,8,8,8,8,8,8,8,8
5,8,8,8,8,8,8,8,8,8,8,8,8,8
2,8,8,8,8,8,8,8,8,8,8,8,8,8
2,2,8,8,8,8,8,8,8,8,8,8,8,8
2,8,8,8,8,8,8,8,8,8,8,8,8,8
5,7,7,7,7,8,2,2,7,5,8,8,8,8
8,8,8,8,8,5,2,2,2,5,8,8,8,8
endlayer

layer
8,8,8,8,8,8,8,5,5,8,8,8,8,8
8,5,8,8,8,8,8,8,7,5,8,8,8,8
8,5,8,8,8,8,8,8,8,5,8,8,8,8
8,5,8,8,8,8,8,8,8,5,8,8,8,8
8,5,8,8,8,8,8,8,8,5,8,8,8,8
8,5,8,8,8,8,8,8,8,5,8,8,8,8
8,5,8,8,8,8,8,8,2,5,8,8,8,8
8,5,7,7,7,7,7,2,7,5,8,8,8,8
8,8,5,5,5,5,5,5,5,8,8,8,8,8
8,8,8,8,8,8,8,8,8,8,8,8,8,8
endlayer

